Workbook

Sheet IS
B6: Particulars ( in millions) | C6: 2023 | D6: =C6+1 -> 2024 | E6: =D6+1 -> 2025 | F6: =E6+1 -> 2026 | G6: =F6+1 -> 2027 | H6: =G6+1 -> 2028 | I6: =H6+1 -> 2029 | J6: =I6+1 -> 2030 | K6: =J6+1 -> 2031
B8: Income
B9: Revenue from operations | C9: 603075.8 | D9: 698290.57 | E9: 691928.88 | F9: =SUM('Revenue Model'!F10:F12) -> 738960.49 | G9: =SUM('Revenue Model'!G10:G12) -> 798254.74 | H9: =SUM('Revenue Model'!H10:H12) -> 862387.41 | I9: =SUM('Revenue Model'!I10:I12) -> 931753.3 | J9: =SUM('Revenue Model'!J10:J12) -> 1006779.4 | K9: =SUM('Revenue Model'!K10:K12) -> 1087927.7
B10: Other income | C10: 11290.62 | D10: 14732.68 | E10: 8700.49 | F10: ='Revised IS'!F20 -> 8700.49 | G10: ='Revised IS'!G20 -> 8700.49 | H10: ='Revised IS'!H20 -> 8700.49 | I10: ='Revised IS'!I20 -> 8700.49 | J10: ='Revised IS'!J20 -> 8700.49 | K10: ='Revised IS'!K20 -> 8700.49
B11: Total income | C11: =SUM(C9:C10) -> 614366.42 | D11: =SUM(D9:D10) -> 713023.25 | E11: =SUM(E9:E10) -> 700629.37 | F11: =SUM(F9:F10) -> 747660.98 | G11: =SUM(G9:G10) -> 806955.23 | H11: =SUM(H9:H10) -> 871087.9 | I11: =SUM(I9:I10) -> 940453.79 | J11: =SUM(J9:J10) -> 1015479.9 | K11: =SUM(K9:K10) -> 1096628.2
B13: Expenses
B14: Cost of materials consumed | C14: 445086.35 | D14: 512979.91 | E14: 493978.87 | F14: =Expense!F26*Expense!F8 -> 527617.79 | G14: =Expense!G26*Expense!G8 -> 569953.89 | H14: =Expense!H26*Expense!H8 -> 615744.61 | I14: =Expense!I26*Expense!I8 -> 665271.85 | J14: =Expense!J26*Expense!J8 -> 718840.52 | K14: =Expense!K26*Expense!K8 -> 776780.39
B15: Purchases of stock-in-trade | C15: 6564.16 | D15: 4334.27 | E15: 7497.41 | F15: =Expense!F27*Expense!F8 -> 6650.6444 | G15: =Expense!G27*Expense!G8 -> 6929.5146 | H15: =Expense!H27*Expense!H8 -> 8197.381 | I15: =Expense!I27*Expense!I8 -> 8443.6359 | J15: =Expense!J27*Expense!J8 -> 9144.3682 | K15: =Expense!K27*Expense!K8 -> 10027.189
B16: Changes in FG, WIP & SIT | C16: -1351.21 | D16: -1384.74 | E16: -1772.37 | F16: =Expense!F28*Expense!F8 -> -1477.921 | G16: =Expense!G28*Expense!G8 -> -1596.5095 | H16: =Expense!H28*Expense!H8 -> -1724.7748 | I16: =Expense!I28*Expense!I8 -> -1863.5066 | J16: =Expense!J28*Expense!J8 -> -2013.5589 | K16: =Expense!K28*Expense!K8 -> -2175.8554
B17: Employee benefits expense | C17: 17662.26 | D17: 19754.88 | E17: 23112.09 | F17: =Expense!F12 -> 22410.138 | G17: =Expense!G12 -> 24208.33 | H17: =Expense!H12 -> 26153.254 | I17: =Expense!I12 -> 28256.883 | J17: =Expense!J12 -> 30532.169 | K17: =Expense!K12 -> 32993.118
B18: Finance costs | C18: 1424.01 | D18: 1580.79 | E18: 1272 | F18: ='Revised IS'!F19 -> 532.06504 | G18: ='Revised IS'!G19 -> 214.77458 | H18: ='Revised IS'!H19 -> 0 | I18: ='Revised IS'!I19 -> 0 | J18: ='Revised IS'!J19 -> 0 | K18: ='Revised IS'!K19 -> 0
B19: Depreciation and amortization expense | C19: 21898.66 | D19: 22079.31 | E19: 21052.58 | F19: ='Revised IS'!F16 -> 23969.298 | G19: ='Revised IS'!G16 -> 27261.177 | H19: ='Revised IS'!H16 -> 29554.264 | I19: ='Revised IS'!I16 -> 30726.982 | J19: ='Revised IS'!J16 -> 33337.99 | K19: ='Revised IS'!K16 -> 36159.142
B20: Other expenses | C20: 60098.7 | D20: 71820.52 | E20: 79989.8 | F20: =Expense!F13 -> 88675.259 | G20: =Expense!G13 -> 97786.206 | H20: =Expense!H13 -> 105642.46 | I20: =Expense!I13 -> 114139.78 | J20: =Expense!J13 -> 123330.48 | K20: =Expense!K13 -> 133271.15
B21: Cost of materials consumed for own use | C21: -472.26 | D21: -540.43 | E21: -414.5 | F21: =Expense!F29*Expense!F8 -> -738.96049 | G21: =Expense!G29*Expense!G8 -> -798.25474 | H21: =Expense!H29*Expense!H8 -> -862.38741 | I21: =Expense!I29*Expense!I8 -> -931.7533 | J21: =Expense!J29*Expense!J8 -> -1006.7794 | K21: =Expense!K29*Expense!K8 -> -1087.9277
B23: Total expenses | C23: =SUM(C14:C21) -> 550910.67 | D23: =SUM(D14:D21) -> 630624.51 | E23: =SUM(E14:E21) -> 624715.88 | F23: =SUM(F14:F21) -> 667638.32 | G23: =SUM(G14:G21) -> 723959.13 | H23: =SUM(H14:H21) -> 782704.8 | I23: =SUM(I14:I21) -> 844043.87 | J23: =SUM(J14:J21) -> 912165.19 | K23: =SUM(K14:K21) -> 985967.2
B25: Profit before tax | C25: =C11-C23 -> 63455.75 | D25: =D11-D23 -> 82398.74 | E25: =E11-E23 -> 75913.49 | F25: =F11-F23 -> 80022.667 | G25: =G11-G23 -> 82996.109 | H25: =H11-H23 -> 88383.095 | I25: =I11-I23 -> 96409.912 | J25: =J11-J23 -> 103314.74 | K25: =K11-K23 -> 110661.01
B27: Total tax expense | C27: =SUM(C31:C32) -> 16363.25 | D27: =SUM(D31:D32) -> 21798.3 | E27: =SUM(E31:E32) -> 19511.35 | F27: ='Revised IS'!F23 -> 20805.894 | G27: ='Revised IS'!G23 -> 21512.746 | H27: ='Revised IS'!H23 -> 23092.937 | I27: ='Revised IS'!I23 -> 25081.62 | J27: ='Revised IS'!J23 -> 26883.504 | K27: ='Revised IS'!K23 -> 28833.18
B29: Profit for the year | C29: =C25-C27 -> 47092.5 | D29: =D25-D27 -> 60600.44 | E29: =E25-E27 -> 56402.14 | F29: =F25-F27 -> 59216.774 | G29: =G25-G27 -> 61483.363 | H29: =H25-H27 -> 65290.158 | I29: =I25-I27 -> 71328.293 | J29: =J25-J27 -> 76431.235 | K29: =K25-K27 -> 81827.826
C31: 18414.53 | D31: 22965.26 | E31: 20322.83
C32: -2051.28 | D32: -1166.96 | E32: -811.48

Sheet Revenue Model
B6: Particulars ( in millions) | C6: 2023 | D6: =C6+1 -> 2024 | E6: =D6+1 -> 2025 | F6: =E6+1 -> 2026 | G6: =F6+1 -> 2027 | H6: =G6+1 -> 2028 | I6: =H6+1 -> 2029 | J6: =I6+1 -> 2030 | K6: =J6+1 -> 2031
B8: Revenue from operations
B10: Sale of products | C10: 559196.04 | D10: 643525.06 | E10: 630827.86 | F10: =SUM(F16:F17) -> 681271.59 | G10: =SUM(G16:G17) -> 736863.35 | H10: =SUM(H16:H17) -> 796991.4 | I10: =SUM(I16:I17) -> 862025.9 | J10: =SUM(J16:J17) -> 932367.21 | K10: =SUM(K16:K17) -> 1008448.4
B11: Sale of services | C11: 31831.84 | D11: 42372.8 | E11: 48595.92 | F11: =F10*F46 -> 45373.66 | G11: =G10*G46 -> 49076.15 | H11: =H10*H46 -> 53080.764 | I11: =I10*I46 -> 57412.154 | J11: =J10*J46 -> 62096.986 | K11: =K10*K46 -> 67164.1
B12: Other operating Revenue | C12: 12047.92 | D12: 12392.71 | E12: 12505.1 | F12: =AVERAGE($C$12:$E$12) -> 12315.243 | G12: =AVERAGE($C$12:$E$12) -> 12315.243 | H12: =AVERAGE($C$12:$E$12) -> 12315.243 | I12: =AVERAGE($C$12:$E$12) -> 12315.243 | J12: =AVERAGE($C$12:$E$12) -> 12315.243 | K12: =AVERAGE($C$12:$E$12) -> 12315.243
B14: Sale of Product
B16: Vehicles | C16: 522709.37 | D16: 600395.44 | E16: 587771.41 | F16: =SUM(F21:F22) -> 635733.56 | G16: =SUM(G21:G22) -> 687609.42 | H16: =SUM(H21:H22) -> 743718.34 | I16: =SUM(I21:I22) -> 804405.76 | J16: =SUM(J21:J22) -> 870045.27 | K16: =SUM(K21:K22) -> 941040.96
B17: Parts | C17: 36486.67 | D17: 43129.62 | E17: 43056.45 | F17: =F16*F44 -> 45538.032 | G17: =G16*G44 -> 49253.936 | H17: =H16*H44 -> 53273.057 | I17: =I16*I44 -> 57620.138 | J17: =J16*J44 -> 62321.942 | K17: =K16*K44 -> 67407.412
B19: Vehicles Revenue
B21: Domestic | C21: 400980.14 | D21: 464979.85 | E21: 459314.42 | F21: =(F26*F31)/1000 -> 496794.48 | G21: =(G26*G31)/1000 -> 537332.91 | H21: =(H26*H31)/1000 -> 581179.27 | I21: =(I26*I31)/1000 -> 628603.5 | J21: =(J26*J31)/1000 -> 679897.55 | K21: =(K26*K31)/1000 -> 735377.18
B22: Exports | C22: 121729.23 | D22: 135415.59 | E22: 128456.99 | F22: =(F27*F32)/1000 -> 138939.08 | G22: =(G27*G32)/1000 -> 150276.51 | H22: =(H27*H32)/1000 -> 162539.07 | I22: =(I27*I32)/1000 -> 175802.26 | J22: =(J27*J32)/1000 -> 190147.73 | K22: =(K27*K32)/1000 -> 205663.78
B24: Units Sold
B26: Domestic | C26: 567546 | D26: 614721 | E26: 598666 | F26: =E26*(1+F41) -> 622612.64 | G26: =F26*(1+G41) -> 647517.15 | H26: =G26*(1+H41) -> 673417.83 | I26: =H26*(1+I41) -> 700354.54 | J26: =I26*(1+J41) -> 728368.73 | K26: =J26*(1+K41) -> 757503.48
B27: Exports | C27: 153019 | D27: 163155 | E27: 163386 | F27: =E27*(1+F42) -> 169921.44 | G27: =F27*(1+G42) -> 176718.3 | H27: =G27*(1+H42) -> 183787.03 | I27: =H27*(1+I42) -> 191138.51 | J27: =I27*(1+J42) -> 198784.05 | K27: =J27*(1+K42) -> 206735.41
B29: Average Selling Price
B31: Domestic | C31: =(C21/C26*1000000)/1000 -> 706.51567 | D31: =(D21/D26*1000000)/1000 -> 756.40795 | E31: =(E21/E26*1000000)/1000 -> 767.22984 | F31: =E31*(1+F36) -> 797.91903 | G31: =F31*(1+G36) -> 829.8358 | H31: =G31*(1+H36) -> 863.02923 | I31: =H31*(1+I36) -> 897.5504 | J31: =I31*(1+J36) -> 933.45241 | K31: =J31*(1+K36) -> 970.79051
B32: Exports | C32: =(C22/C27*1000000)/1000 -> 795.51709 | D32: =(D22/D27*1000000)/1000 -> 829.98124 | E32: =(E22/E27*1000000)/1000 -> 786.21785 | F32: =E32*(1+F37) -> 817.66657 | G32: =F32*(1+G37) -> 850.37323 | H32: =G32*(1+H37) -> 884.38816 | I32: =H32*(1+I37) -> 919.76368 | J32: =I32*(1+J37) -> 956.55423 | K32: =J32*(1+K37) -> 994.8164
B34: Average Selling Price Growth Rate
B36: Domestic | D36: =D31/C31-1 -> 0.070617375 | E36: =E31/D31-1 -> 0.014306954 | F36: 0.04 | G36: 0.04 | H36: 0.04 | I36: 0.04 | J36: 0.04 | K36: 0.04
B37: Exports | D37: =D32/C32-1 -> 0.043322956 | E37: =E32/D32-1 -> -0.052728171 | F37: 0.04 | G37: 0.04 | H37: 0.04 | I37: 0.04 | J37: 0.04 | K37: 0.04
B39: Unit Sold Growth Rate
B41: Domestic | D41: =D26/C26-1 -> 0.083121016 | E41: =E26/D26-1 -> -0.02611754 | F41: 0.04 | G41: 0.04 | H41: 0.04 | I41: 0.04 | J41: 0.04 | K41: 0.04
B42: Exports | D42: =D27/C27-1 -> 0.06624014 | E42: =E27/D27-1 -> 0.0014158316 | F42: 0.04 | G42: 0.04 | H42: 0.04 | I42: 0.04 | J42: 0.04 | K42: 0.04
B44: Parts Revenue as a % of Vehicle Revenue | C44: =C17/C16 -> 0.069802977 | D44: =D17/D16 -> 0.071835356 | E44: =E17/E16 -> 0.073253733 | F44: =AVERAGE($C44:$E44) -> 0.071630689 | G44: =AVERAGE($C44:$E44) -> 0.071630689 | H44: =AVERAGE($C44:$E44) -> 0.071630689 | I44: =AVERAGE($C44:$E44) -> 0.071630689 | J44: =AVERAGE($C44:$E44) -> 0.071630689 | K44: =AVERAGE($C44:$E44) -> 0.071630689
B46: Sales of Service as a % of Revenue | C46: =C11/C10 -> 0.056924294 | D46: =D11/D10 -> 0.065844833 | E46: =E11/E10 -> 0.077035152 | F46: =AVERAGE($C46:$E46) -> 0.066601426 | G46: =AVERAGE($C46:$E46) -> 0.066601426 | H46: =AVERAGE($C46:$E46) -> 0.066601426 | I46: =AVERAGE($C46:$E46) -> 0.066601426 | J46: =AVERAGE($C46:$E46) -> 0.066601426 | K46: =AVERAGE($C46:$E46) -> 0.066601426

Sheet Expense
B6: Particulars ( in millions) | C6: 2023 | D6: =C6+1 -> 2024 | E6: =D6+1 -> 2025 | F6: =E6+1 -> 2026 | G6: =F6+1 -> 2027 | H6: =G6+1 -> 2028 | I6: =H6+1 -> 2029 | J6: =I6+1 -> 2030 | K6: =J6+1 -> 2031
B8: Revenue | C8: ='Revised IS'!C8 -> 603075.8 | D8: ='Revised IS'!D8 -> 698290.57 | E8: ='Revised IS'!E8 -> 691928.88 | F8: ='Revised IS'!F8 -> 738960.49 | G8: ='Revised IS'!G8 -> 798254.74 | H8: ='Revised IS'!H8 -> 862387.41 | I8: ='Revised IS'!I8 -> 931753.3 | J8: ='Revised IS'!J8 -> 1006779.4 | K8: ='Revised IS'!K8 -> 1087927.7
B11: COGS | C11: 449827.04 | D11: 515389.01 | E11: 499289.41 | F11: =F8*F19 -> 532051.55 | G11: =G8*G19 -> 574743.42 | H11: =H8*H19 -> 620918.93 | I11: =I8*I19 -> 670862.37 | J11: =J8*J19 -> 724881.2 | K11: =K8*K19 -> 783307.96
B12: Employee Benefit Expense | C12: 17662.26 | D12: 19754.88 | E12: 23112.09 | F12: =F8*F20 -> 22410.138 | G12: =G8*G20 -> 24208.33 | H12: =H8*H20 -> 26153.254 | I12: =I8*I20 -> 28256.883 | J12: =J8*J20 -> 30532.169 | K12: =K8*K20 -> 32993.118
B13: Other Expenses | C13: 60098.7 | D13: 71820.52 | E13: 79989.8 | F13: =F8*F21 -> 88675.259 | G13: =G8*G21 -> 97786.206 | H13: =H8*H21 -> 105642.46 | I13: =I8*I21 -> 114139.78 | J13: =J8*J21 -> 123330.48 | K13: =K8*K21 -> 133271.15
B14: Tax | C14: 16363.25 | D14: 21798.3 | E14: 19511.35 | F14: =F15*'Revised IS'!F22 -> 20805.894 | G14: =G15*'Revised IS'!G22 -> 21512.746 | H14: =H15*'Revised IS'!H22 -> 23092.937 | I14: =I15*'Revised IS'!I22 -> 25081.62 | J14: =J15*'Revised IS'!J22 -> 26883.504 | K14: =K15*'Revised IS'!K22 -> 28833.18
C15: =C14/'Revised IS'!C22 -> 0.25786867 | D15: =D14/'Revised IS'!D22 -> 0.26454652 | E15: =E14/'Revised IS'!E22 -> 0.25702085 | F15: 0.26 | G15: 0.26 | H15: 0.26 | I15: 0.26 | J15: 0.26 | K15: 0.26
B17: As a % of Revenue
B19: COGS | C19: =C11/C8 -> 0.74588806 | D19: =D11/D8 -> 0.73807242 | E19: =E11/E8 -> 0.72159065 | F19: 0.72 | G19: 0.72 | H19: 0.72 | I19: 0.72 | J19: 0.72 | K19: 0.72
B20: Employee Benefit Expense | C20: =C12/C8 -> 0.029286965 | D20: =D12/D8 -> 0.028290343 | E20: =E12/E8 -> 0.033402407 | F20: =AVERAGE($C20:$E20) -> 0.030326572 | G20: =AVERAGE($C20:$E20) -> 0.030326572 | H20: =AVERAGE($C20:$E20) -> 0.030326572 | I20: =AVERAGE($C20:$E20) -> 0.030326572 | J20: =AVERAGE($C20:$E20) -> 0.030326572 | K20: =AVERAGE($C20:$E20) -> 0.030326572
B21: Other Expense | C21: =C13/C8 -> 0.099653642 | D21: =D13/D8 -> 0.10285191 | E21: =E13/E8 -> 0.11560408 | F21: 0.12 | G21: 0.1225 | H21: 0.1225 | I21: 0.1225 | J21: 0.1225 | K21: 0.1225
C26: =IS!C14/IS!C9 -> 0.73802721 | D26: =IS!D14/IS!D9 -> 0.73462242 | E26: =IS!E14/IS!E9 -> 0.71391567 | F26: 0.714 | G26: 0.714 | H26: 0.714 | I26: 0.714 | J26: 0.714 | K26: 0.714
C27: =IS!C15/IS!C9 -> 0.010884469 | D27: =IS!D15/IS!D9 -> 0.006206972 | E27: =IS!E15/IS!E9 -> 0.010835521 | F27: =0.9% -> 0.009 | G27: =AVERAGE(D27:F27) -> 0.008680831 | H27: =AVERAGE(E27:G27) -> 0.0095054507 | I27: =AVERAGE(F27:H27) -> 0.0090620939 | J27: =AVERAGE(G27:I27) -> 0.0090827919 | K27: =AVERAGE(H27:J27) -> 0.0092167788
C28: =IS!C16/IS!C9 -> -0.002240531 | D28: =IS!D16/IS!D9 -> -0.0019830427 | E28: =IS!E16/IS!E9 -> -0.0025614916 | F28: =-0.2% -> -0.002 | G28: =-0.2% -> -0.002 | H28: =-0.2% -> -0.002 | I28: =-0.2% -> -0.002 | J28: =-0.2% -> -0.002 | K28: =-0.2% -> -0.002
C29: =IS!C21/IS!C9 -> -0.00078308564 | D29: =IS!D21/IS!D9 -> -0.00077393283 | E29: =IS!E21/IS!E9 -> -0.00059905001 | F29: =-0.1% -> -0.001 | G29: =-0.1% -> -0.001 | H29: =-0.1% -> -0.001 | I29: =-0.1% -> -0.001 | J29: =-0.1% -> -0.001 | K29: =-0.1% -> -0.001

Sheet CFS
B6: Particulars ( in millions) | C6: 2023 | D6: =C6+1 -> 2024 | E6: =D6+1 -> 2025 | F6: =E6+1 -> 2026 | G6: =F6+1 -> 2027 | H6: =G6+1 -> 2028 | I6: =H6+1 -> 2029 | J6: =I6+1 -> 2030 | K6: =J6+1 -> 2031
B8: PAT | F8: ='Revised IS'!F25 -> 59216.774 | G8: ='Revised IS'!G25 -> 61228.585 | H8: ='Revised IS'!H25 -> 65726.052 | I8: ='Revised IS'!I25 -> 71386.149 | J8: ='Revised IS'!J25 -> 76514.589 | K8: ='Revised IS'!K25 -> 82063.666
B9: D&A | F9: ='Revised IS'!F16 -> 23969.298 | G9: ='Revised IS'!G16 -> 27261.177 | H9: ='Revised IS'!H16 -> 29554.264 | I9: ='Revised IS'!I16 -> 30726.982 | J9: ='Revised IS'!J16 -> 33337.99 | K9: ='Revised IS'!K16 -> 36159.142
B10: SBC | F10: =0 -> 0 | G10: =0 -> 0 | H10: =0 -> 0 | I10: =0 -> 0 | J10: =0 -> 0 | K10: =0 -> 0
B11: Change in
B12: Inventories | F12: =-(BS!F23-BS!E23) -> -2977.7731 | G12: =-(BS!G23-BS!F23) -> -2970.5957 | H12: =-(BS!H23-BS!G23) -> -3212.9963 | I12: =-(BS!I23-BS!H23) -> -3475.1768 | J12: =-(BS!J23-BS!I23) -> -3758.7512 | K12: =-(BS!K23-BS!J23) -> -4065.4653
B13: Trade receivable | F13: =-(BS!F25-BS!E25) -> -6199.2197 | G13: =-(BS!G25-BS!F25) -> -2414.4602 | H13: =-(BS!H25-BS!G25) -> -2611.4802 | I13: =-(BS!I25-BS!H25) -> -2824.577 | J13: =-(BS!J25-BS!I25) -> -3055.0624 | K13: =-(BS!K25-BS!J25) -> -3304.3555
B14: Others | F14: =-(SUM(BS!F27:F30)-SUM(BS!E27:E30)) -> 0 | G14: =-(SUM(BS!G27:G30)-SUM(BS!F27:F30)) -> 0 | H14: =-(SUM(BS!H27:H30)-SUM(BS!G27:G30)) -> 0 | I14: =-(SUM(BS!I27:I30)-SUM(BS!H27:H30)) -> 0 | J14: =-(SUM(BS!J27:J30)-SUM(BS!I27:I30)) -> 0 | K14: =-(SUM(BS!K27:K30)-SUM(BS!J27:J30)) -> 0
B15: Change in
B16: Trade Payable | F16: =SUM(BS!F58:F59)-SUM(BS!E58:E59) -> 10062.126 | G16: =SUM(BS!G58:G59)-SUM(BS!F58:F59) -> 6493.3651 | H16: =SUM(BS!H58:H59)-SUM(BS!G58:G59) -> 7023.2237 | I16: =SUM(BS!I58:I59)-SUM(BS!H58:H59) -> 7596.3188 | J16: =SUM(BS!J58:J59)-SUM(BS!I58:I59) -> 8216.1784 | K16: =SUM(BS!K58:K59)-SUM(BS!J58:J59) -> 8886.6185
B17: Others | F17: =SUM(BS!F60:F63)-SUM(BS!E60:E63) -> 0 | G17: =SUM(BS!G60:G63)-SUM(BS!F60:F63) -> 0 | H17: =SUM(BS!H60:H63)-SUM(BS!G60:G63) -> 0 | I17: =SUM(BS!I60:I63)-SUM(BS!H60:H63) -> 0 | J17: =SUM(BS!J60:J63)-SUM(BS!I60:I63) -> 0 | K17: =SUM(BS!K60:K63)-SUM(BS!J60:J63) -> 0
B19: Cash From Operations: CFO | F19: =SUM(F8:F17) -> 84071.205 | G19: =SUM(G8:G17) -> 89598.071 | H19: =SUM(H8:H17) -> 96479.063 | I19: =SUM(I8:I17) -> 103409.7 | J19: =SUM(J8:J17) -> 111254.94 | K19: =SUM(K8:K17) -> 119739.61
B21: CapEx on PP&E | F21: =-'BS shcedule'!F14 -> -22767.635 | G21: =-'BS shcedule'!G14 -> -24594.512 | H21: =-'BS shcedule'!H14 -> -26570.463 | I21: =-'BS shcedule'!I14 -> -28707.65 | J21: =-'BS shcedule'!J14 -> -31019.232 | K21: =-'BS shcedule'!K14 -> -33519.44
B22: Additions to Intangibles | F22: =-'BS shcedule'!F36 -> -760.81024 | G22: =-'BS shcedule'!G36 -> -821.85772 | H22: =-'BS shcedule'!H36 -> -887.88667 | I22: =-'BS shcedule'!I36 -> 0 | J22: =-'BS shcedule'!J36 -> 0 | K22: =-'BS shcedule'!K36 -> 0
B23: Additions to Right to Use | F23: =-'BS shcedule'!F51 -> -2092.2213 | G23: =-'BS shcedule'!G51 -> -2260.1013 | H23: =-'BS shcedule'!H51 -> -2441.6803 | I23: =-'BS shcedule'!I51 -> -2638.0762 | J23: =-'BS shcedule'!J51 -> -2850.498 | K23: =-'BS shcedule'!K51 -> -3080.2533
B25: Cash From Investment: CFI | F25: =SUM(F21:F23) -> -25620.667 | G25: =SUM(G21:G23) -> -27676.471 | H25: =SUM(H21:H23) -> -29900.03 | I25: =SUM(I21:I23) -> -31345.726 | J25: =SUM(J21:J23) -> -33869.73 | K25: =SUM(K21:K23) -> -36599.693
B27: Dividend | F27: =-'Revised IS'!F26 -> -17914.872 | G27: =-'Revised IS'!G26 -> -18523.506 | H27: =-'Revised IS'!H26 -> -19884.126 | I27: =-'Revised IS'!I26 -> -21596.478 | J27: =-'Revised IS'!J26 -> -23147.986 | K27: =-'Revised IS'!K26 -> -24826.751
B28: Equity Issue | F28: 0 | G28: 0 | H28: 0 | I28: 0 | J28: 0 | K28: 0
B29: Equity Buyback | F29: 0 | G29: 0 | H29: 0 | I29: 0 | J29: 0 | K29: 0
B30: Options Conversions | F30: 0 | G30: 0 | H30: 0 | I30: 0 | J30: 0 | K30: 0
B31: Change in Debt | F31: =Debt!F22-Debt!E22 -> -2558.37 | G31: =Debt!G22-Debt!F22 -> -5359.88 | H31: =Debt!H22-Debt!G22 -> 0 | I31: =Debt!I22-Debt!H22 -> 0 | J31: =Debt!J22-Debt!I22 -> 0 | K31: =Debt!K22-Debt!J22 -> 0
B33: Cash from Financing: CFF | F33: =SUM(F27:F31) -> -20473.242 | G33: =SUM(G27:G31) -> -23883.386 | H33: =SUM(H27:H31) -> -19884.126 | I33: =SUM(I27:I31) -> -21596.478 | J33: =SUM(J27:J31) -> -23147.986 | K33: =SUM(K27:K31) -> -24826.751
B35: Surplus / Deficit | F35: =SUM(F19,F25,F33) -> 37977.296 | G35: =SUM(G19,G25,G33) -> 38038.214 | H35: =SUM(H19,H25,H33) -> 46694.907 | I35: =SUM(I19,I25,I33) -> 50467.492 | J35: =SUM(J19,J25,J33) -> 54237.227 | K35: =SUM(K19,K25,K33) -> 58313.162
B36: Openning Cash Balance | F36: =BS!E26 -> 48457.17 | G36: =BS!F26 -> 86434.466 | H36: =BS!G26 -> 124472.68 | I36: =BS!H26 -> 171167.59 | J36: =BS!I26 -> 221635.08 | K36: =BS!J26 -> 275872.3
B38: Closing Cash Balance | F38: =SUM(F35:F36) -> 86434.466 | G38: =SUM(G35:G36) -> 124472.68 | H38: =SUM(H35:H36) -> 171167.59 | I38: =SUM(I35:I36) -> 221635.08 | J38: =SUM(J35:J36) -> 275872.3 | K38: =SUM(K35:K36) -> 334185.47

Sheet Revised IS
B6: Particulars ( in millions) | C6: 2023 | D6: =C6+1 -> 2024 | E6: =D6+1 -> 2025 | F6: =E6+1 -> 2026 | G6: =F6+1 -> 2027 | H6: =G6+1 -> 2028 | I6: =H6+1 -> 2029 | J6: =I6+1 -> 2030 | K6: =J6+1 -> 2031
B8: Revenue from operations | C8: =IS!C9 -> 603075.8 | D8: =IS!D9 -> 698290.57 | E8: =IS!E9 -> 691928.88 | F8: =IS!F9 -> 738960.49 | G8: =IS!G9 -> 798254.74 | H8: =IS!H9 -> 862387.41 | I8: =IS!I9 -> 931753.3 | J8: =IS!J9 -> 1006779.4 | K8: =IS!K9 -> 1087927.7
B9: COGS | C9: =SUM(IS!C14:C16,IS!C21) -> 449827.04 | D9: =SUM(IS!D14:D16,IS!D21) -> 515389.01 | E9: =SUM(IS!E14:E16,IS!E21) -> 499289.41 | F9: =Expense!F11 -> 532051.55 | G9: =Expense!G11 -> 574743.42 | H9: =Expense!H11 -> 620918.93 | I9: =Expense!I11 -> 670862.37 | J9: =Expense!J11 -> 724881.2 | K9: =Expense!K11 -> 783307.96
B11: Gross Profit | C11: =C8-C9 -> 153248.76 | D11: =D8-D9 -> 182901.56 | E11: =E8-E9 -> 192639.47 | F11: =F8-F9 -> 206908.94 | G11: =G8-G9 -> 223511.33 | H11: =H8-H9 -> 241468.47 | I11: =I8-I9 -> 260890.92 | J11: =J8-J9 -> 281898.24 | K11: =K8-K9 -> 304619.76
B12: Employee Benefit Expense | C12: =IS!C17 -> 17662.26 | D12: =IS!D17 -> 19754.88 | E12: =IS!E17 -> 23112.09 | F12: =Expense!F12 -> 22410.138 | G12: =Expense!G12 -> 24208.33 | H12: =Expense!H12 -> 26153.254 | I12: =Expense!I12 -> 28256.883 | J12: =Expense!J12 -> 30532.169 | K12: =Expense!K12 -> 32993.118
B13: Other Expenses | C13: =IS!C20 -> 60098.7 | D13: =IS!D20 -> 71820.52 | E13: =IS!E20 -> 79989.8 | F13: =Expense!F13 -> 88675.259 | G13: =Expense!G13 -> 97786.206 | H13: =Expense!H13 -> 105642.46 | I13: =Expense!I13 -> 114139.78 | J13: =Expense!J13 -> 123330.48 | K13: =Expense!K13 -> 133271.15
B15: EBITDA | C15: =(C11-SUM(C12:C13)) -> 75487.8 | D15: =(D11-SUM(D12:D13)) -> 91326.16 | E15: =(E11-SUM(E12:E13)) -> 89537.58 | F15: =(F11-SUM(F12:F13)) -> 95823.54 | G15: =(G11-SUM(G12:G13)) -> 101516.79 | H15: =(H11-SUM(H12:H13)) -> 109672.76 | I15: =(I11-SUM(I12:I13)) -> 118494.26 | J15: =(J11-SUM(J12:J13)) -> 128035.59 | K15: =(K11-SUM(K12:K13)) -> 138355.5
B16: D&A | C16: =IS!C19 -> 21898.66 | D16: =IS!D19 -> 22079.31 | E16: =IS!E19 -> 21052.58 | F16: ='BS shcedule'!F66 -> 23969.298 | G16: ='BS shcedule'!G66 -> 27261.177 | H16: ='BS shcedule'!H66 -> 29554.264 | I16: ='BS shcedule'!I66 -> 30726.982 | J16: ='BS shcedule'!J66 -> 33337.99 | K16: ='BS shcedule'!K66 -> 36159.142
B18: EBIT | C18: =C15-C16 -> 53589.14 | D18: =D15-D16 -> 69246.85 | E18: =E15-E16 -> 68485 | F18: =F15-F16 -> 71854.242 | G18: =G15-G16 -> 74255.615 | H18: =H15-H16 -> 80118.499 | I18: =I15-I16 -> 87767.279 | J18: =J15-J16 -> 94697.603 | K18: =K15-K16 -> 102196.36
B19: Finance Cost | C19: =IS!C18 -> 1424.01 | D19: =IS!D18 -> 1580.79 | E19: =IS!E18 -> 1272 | F19: =Debt!F24 -> 532.06504 | G19: =Debt!G24 -> 214.77458 | H19: =Debt!H24 -> 0 | I19: =Debt!I24 -> 0 | J19: =Debt!J24 -> 0 | K19: =Debt!K24 -> 0
B20: Other Incomes | C20: =IS!C10 -> 11290.62 | D20: =IS!D10 -> 14732.68 | E20: =IS!E10 -> 8700.49 | F20: =E20 -> 8700.49 | G20: =F20 -> 8700.49 | H20: =G20 -> 8700.49 | I20: =H20 -> 8700.49 | J20: =I20 -> 8700.49 | K20: =J20 -> 8700.49
B22: Pretax Income | C22: =C18-C19+C20 -> 63455.75 | D22: =D18-D19+D20 -> 82398.74 | E22: =E18-E19+E20 -> 75913.49 | F22: =F18-F19+F20 -> 80022.667 | G22: =G18-G19+G20 -> 82741.331 | H22: =H18-H19+H20 -> 88818.989 | I22: =I18-I19+I20 -> 96467.769 | J22: =J18-J19+J20 -> 103398.09 | K22: =K18-K19+K20 -> 110896.85
B23: Tax | C23: =IS!C27 -> 16363.25 | D23: =IS!D27 -> 21798.3 | E23: =IS!E27 -> 19511.35 | F23: =Expense!F14 -> 20805.894 | G23: =Expense!G14 -> 21512.746 | H23: =Expense!H14 -> 23092.937 | I23: =Expense!I14 -> 25081.62 | J23: =Expense!J14 -> 26883.504 | K23: =Expense!K14 -> 28833.18
B25: PAT | C25: =C22-C23 -> 47092.5 | D25: =D22-D23 -> 60600.44 | E25: =E22-E23 -> 56402.14 | F25: =F22-F23 -> 59216.774 | G25: =G22-G23 -> 61228.585 | H25: =H22-H23 -> 65726.052 | I25: =I22-I23 -> 71386.149 | J25: =J22-J23 -> 76514.589 | K25: =K22-K23 -> 82063.666
B26: Dividend | F26: =F25*F36 -> 17914.872 | G26: =G25*G36 -> 18523.506 | H26: =H25*H36 -> 19884.126 | I26: =I25*I36 -> 21596.478 | J26: =J25*J36 -> 23147.986 | K26: =K25*K36 -> 24826.751
B28: Retained Earning | F28: =F25-F26 -> 41301.902 | G28: =G25-G26 -> 42705.079 | H28: =H25-H26 -> 45841.925 | I28: =I25-I26 -> 49789.671 | J28: =J25-J26 -> 53366.602 | K28: =K25-K26 -> 57236.915
B30: Dividend Per Share | E30: 21 | F30: =F26/F32 -> 22.035513 | G30: =G26/G32 -> 22.78414 | H30: =H26/H32 -> 24.45772 | I30: =I26/I32 -> 26.563933 | J30: =J26/J32 -> 28.472308 | K30: =K26/K32 -> 30.537209
B32: Shares | E32: 813 | F32: 813 | G32: 813 | H32: 813 | I32: 813 | J32: 813 | K32: 813
B34: Total Dividend | E34: 17063.36
E36: =E34/E25 -> 0.30253036 | F36: =E36 -> 0.30253036 | G36: =F36 -> 0.30253036 | H36: =G36 -> 0.30253036 | I36: =H36 -> 0.30253036 | J36: =I36 -> 0.30253036 | K36: =J36 -> 0.30253036

Sheet BS
B6: Particulars ( in millions) | C6: 2023 | D6: =C6+1 -> 2024 | E6: =D6+1 -> 2025 | F6: =E6+1 -> 2026 | G6: =F6+1 -> 2027 | H6: =G6+1 -> 2028 | I6: =H6+1 -> 2029 | J6: =I6+1 -> 2030 | K6: =J6+1 -> 2031
B8: Assets
B9: Non-current assets
B10: Property, plant and equipment | C10: 57656.36 | D10: 67135.59 | E10: 62907.54 | F10: ='BS shcedule'!F27 -> 87627.218 | G10: ='BS shcedule'!G27 -> 84783.115 | H10: ='BS shcedule'!H27 -> 81634.593 | I10: ='BS shcedule'!I27 -> 78159.597 | J10: ='BS shcedule'!J27 -> 74334.274 | K10: ='BS shcedule'!K27 -> 70132.823
B11: Capital work-in-progress | C11: 13366.35 | D11: 6528.42 | E11: 47183.61 | F11: ='BS shcedule'!F16 -> 22767.635 | G11: ='BS shcedule'!G16 -> 24594.512 | H11: ='BS shcedule'!H16 -> 26570.463 | I11: ='BS shcedule'!I16 -> 28707.65 | J11: ='BS shcedule'!J16 -> 31019.232 | K11: ='BS shcedule'!K16 -> 33519.44
B12: Right-of-use assets | C12: 577.65 | D12: 6183.42 | E12: 6192.5 | F12: ='BS shcedule'!F58 -> 7921.2095 | G12: ='BS shcedule'!G58 -> 9719.8717 | H12: ='BS shcedule'!H58 -> 11594.323 | I12: ='BS shcedule'!I58 -> 13550.875 | J12: ='BS shcedule'!J58 -> 15596.357 | K12: ='BS shcedule'!K58 -> 17738.151
B13: Intangible assets | C13: 3270.32 | D13: 2825.26 | E13: 1951.01 | F13: ='BS shcedule'!F43 -> 1569.9662 | G13: ='BS shcedule'!G43 -> 1203.8239 | H13: ='BS shcedule'!H43 -> 847.71061 | I13: ='BS shcedule'!I43 -> 847.71061 | J13: ='BS shcedule'!J43 -> 847.71061 | K13: ='BS shcedule'!K43 -> 847.71061
B14: Financial assets
B15: Other financial assets | C15: 516.97 | D15: 624.12 | E15: 774.01 | F15: =E15 -> 774.01 | G15: =F15 -> 774.01 | H15: =G15 -> 774.01 | I15: =H15 -> 774.01 | J15: =I15 -> 774.01 | K15: =J15 -> 774.01
B16: Deferred tax assets (net) | C16: 8265.99 | D16: 9477.9 | E16: 10320.99 | F16: =E16 -> 10320.99 | G16: =F16 -> 10320.99 | H16: =G16 -> 10320.99 | I16: =H16 -> 10320.99 | J16: =I16 -> 10320.99 | K16: =J16 -> 10320.99
B17: Non-current tax assets (net) | C17: 6146.71 | D17: 6886.39 | E17: 6465.27 | F17: =E17 -> 6465.27 | G17: =F17 -> 6465.27 | H17: =G17 -> 6465.27 | I17: =H17 -> 6465.27 | J17: =I17 -> 6465.27 | K17: =J17 -> 6465.27
B18: Other non-current assets | C18: 2313.36 | D18: 2590.92 | E18: 4855.25 | F18: =E18 -> 4855.25 | G18: =F18 -> 4855.25 | H18: =G18 -> 4855.25 | I18: =H18 -> 4855.25 | J18: =I18 -> 4855.25 | K18: =J18 -> 4855.25
B20: Total non-current assets | C20: 92113.71 | D20: 102252.02 | E20: 140650.18 | F20: =SUM(F10:F18) -> 142301.55 | G20: =SUM(G10:G18) -> 142716.84 | H20: =SUM(H10:H18) -> 143062.61 | I20: =SUM(I10:I18) -> 143681.35 | J20: =SUM(J10:J18) -> 144213.09 | K20: =SUM(K10:K18) -> 144653.64
B22: Current assets
B23: Inventories | C23: 34224.09 | D23: 33156.29 | E23: 34043.57 | F23: ='BS shcedule'!F70 -> 37021.343 | G23: ='BS shcedule'!G70 -> 39991.939 | H23: ='BS shcedule'!H70 -> 43204.935 | I23: ='BS shcedule'!I70 -> 46680.112 | J23: ='BS shcedule'!J70 -> 50438.863 | K23: ='BS shcedule'!K70 -> 54504.328
B24: Financial assets
B25: Trade receivables | C25: 28971.92 | D25: 25100.26 | E25: 23891.23 | F25: ='BS shcedule'!F71 -> 30090.45 | G25: ='BS shcedule'!G71 -> 32504.91 | H25: ='BS shcedule'!H71 -> 35116.39 | I25: ='BS shcedule'!I71 -> 37940.967 | J25: ='BS shcedule'!J71 -> 40996.029 | K25: ='BS shcedule'!K71 -> 44300.385
B26: Cash and cash equivalents | C26: 177411.47 | D26: 9732.15 | E26: 48457.17 | F26: =CFS!F38 -> 86434.466 | G26: =CFS!G38 -> 124472.68 | H26: =CFS!H38 -> 171167.59 | I26: =CFS!I38 -> 221635.08 | J26: =CFS!J38 -> 275872.3 | K26: =CFS!K38 -> 334185.47
B27: Bank balance other than above | C27: 0 | D27: 80441.3 | E27: 37334.53 | F27: =E27 -> 37334.53 | G27: =F27 -> 37334.53 | H27: =G27 -> 37334.53 | I27: =H27 -> 37334.53 | J27: =I27 -> 37334.53 | K27: =J27 -> 37334.53
B28: Loans | C28: 659.48 | D28: 0 | E28: 0 | F28: =0 -> 0 | G28: =0 -> 0 | H28: =0 -> 0 | I28: =0 -> 0 | J28: =0 -> 0 | K28: =0 -> 0
B29: Other financial assets | C29: 4539.58 | D29: 3439.24 | E29: 4572.66 | F29: =E29 -> 4572.66 | G29: =F29 -> 4572.66 | H29: =G29 -> 4572.66 | I29: =H29 -> 4572.66 | J29: =I29 -> 4572.66 | K29: =J29 -> 4572.66
B30: Other current assets | C30: 7813.17 | D30: 9371.19 | E30: 12024.25 | F30: =E30 -> 12024.25 | G30: =F30 -> 12024.25 | H30: =G30 -> 12024.25 | I30: =H30 -> 12024.25 | J30: =I30 -> 12024.25 | K30: =J30 -> 12024.25
B32: Total current assets | C32: =SUM(C23:C30) -> 253619.71 | D32: =SUM(D23:D30) -> 161240.43 | E32: =SUM(E23:E30) -> 160323.41 | F32: =SUM(F23:F30) -> 207477.7 | G32: =SUM(G23:G30) -> 250900.97 | H32: =SUM(H23:H30) -> 303420.35 | I32: =SUM(I23:I30) -> 360187.6 | J32: =SUM(J23:J30) -> 421238.64 | K32: =SUM(K23:K30) -> 486921.62
B34: Total assets | C34: 345733.42 | D34: 263492.45 | E34: 300973.59 | F34: =SUM(F32+F20) -> 349779.25 | G34: =SUM(G32+G20) -> 393617.81 | H34: =SUM(H32+H20) -> 446482.96 | I34: =SUM(I32+I20) -> 503868.95 | J34: =SUM(J32+J20) -> 565451.73 | K34: =SUM(K32+K20) -> 631575.26
B36: Equity and liabilities
B37: Equity
B38: Equity share capital | C38: 8125.41 | D38: 8125.41 | E38: 8125.41 | F38: =E38 -> 8125.41 | G38: =F38 -> 8125.41 | H38: =G38 -> 8125.41 | I38: =H38 -> 8125.41 | J38: =I38 -> 8125.41 | K38: =J38 -> 8125.41
B39: Reserves and surplus | C39: 192422.77 | D39: 98531.16 | E39: 154839.24 | F39: =E39+'Revised IS'!F28 -> 196141.14 | G39: =F39+'Revised IS'!G28 -> 238846.22 | H39: =G39+'Revised IS'!H28 -> 284688.15 | I39: =H39+'Revised IS'!I28 -> 334477.82 | J39: =I39+'Revised IS'!J28 -> 387844.42 | K39: =J39+'Revised IS'!K28 -> 445081.33
B41: Total equity | C41: =SUM(C38:C39) -> 200548.18 | D41: =SUM(D38:D39) -> 106656.57 | E41: =SUM(E38:E39) -> 162964.65 | F41: =SUM(F38:F39) -> 204266.55 | G41: =SUM(G38:G39) -> 246971.63 | H41: =SUM(H38:H39) -> 292813.56 | I41: =SUM(I38:I39) -> 342603.23 | J41: =SUM(J38:J39) -> 395969.83 | K41: =SUM(K38:K39) -> 453206.74
B43: Liabilities
B44: Non-current liabilities
B45: Financial liabilities
B46: Borrowings | C46: 7065.66 | D46: 6227.97 | E46: 5359.88 | F46: =Debt!G22 -> 0 | G46: =Debt!H22 -> 0 | H46: =Debt!I22 -> 0 | I46: =Debt!J22 -> 0 | J46: =Debt!K22 -> 0 | K46: =Debt!L22 -> 0
B47: Lease liabilities | C47: 267.23 | D47: 557.68 | E47: 474.38 | F47: 474.38 | G47: 474.38 | H47: 474.38 | I47: 474.38 | J47: 474.38 | K47: 474.38
B48: Provisions | C48: 8037.65 | D48: 8467.39 | E48: 8736.37 | F48: 8736.37 | G48: 8736.37 | H48: 8736.37 | I48: 8736.37 | J48: 8736.37 | K48: 8736.37
B49: Other non-current liabilities | C49: 9759.55 | D49: 11610.97 | E49: 10775.08 | F49: 10775.08 | G49: 10775.08 | H49: 10775.08 | I49: 10775.08 | J49: 10775.08 | K49: 10775.08
B51: Total non-current liabilities | C51: =SUM(C46:C49) -> 25130.09 | D51: =SUM(D46:D49) -> 26864.01 | E51: =SUM(E46:E49) -> 25345.71 | F51: =SUM(F46:F49) -> 19985.83 | G51: =SUM(G46:G49) -> 19985.83 | H51: =SUM(H46:H49) -> 19985.83 | I51: =SUM(I46:I49) -> 19985.83 | J51: =SUM(J46:J49) -> 19985.83 | K51: =SUM(K46:K49) -> 19985.83
B53: Current liabilities
B54: Financial liabilities
B55: Borrowings | C55: 4520.34 | D55: 1451.18 | E55: 2558.37 | F55: =Debt!F13 -> 5359.88 | G55: =Debt!G13 -> 0 | H55: =Debt!H13 -> 0 | I55: =Debt!I13 -> 0 | J55: =Debt!J13 -> 0 | K55: =Debt!K13 -> 0
...

Sheet BS shcedule
B6: Particulars ( in millions) | C6: 2023 | D6: =C6+1 -> 2024 | E6: =D6+1 -> 2025 | F6: =E6+1 -> 2026 | G6: =F6+1 -> 2027 | H6: =G6+1 -> 2028 | I6: =H6+1 -> 2029 | J6: =I6+1 -> 2030 | K6: =J6+1 -> 2031
B8: Revenue | C8: =IS!C9 -> 603075.8 | D8: =IS!D9 -> 698290.57 | E8: =IS!E9 -> 691928.88 | F8: =IS!F9 -> 738960.49 | G8: =IS!G9 -> 798254.74 | H8: =IS!H9 -> 862387.41 | I8: =IS!I9 -> 931753.3 | J8: =IS!J9 -> 1006779.4 | K8: =IS!K9 -> 1087927.7
B9: cogs | C9: =Expense!C11 -> 449827.04 | D9: =Expense!D11 -> 515389.01 | E9: =Expense!E11 -> 499289.41 | F9: =Expense!F11 -> 532051.55 | G9: =Expense!G11 -> 574743.42 | H9: =Expense!H11 -> 620918.93 | I9: =Expense!I11 -> 670862.37 | J9: =Expense!J11 -> 724881.2 | K9: =Expense!K11 -> 783307.96
B11: PP&E
B13: Openning Cap WIP | F13: =E16 -> 47183.61 | G13: =F16 -> 22767.635 | H13: =G16 -> 24594.512 | I13: =H16 -> 26570.463 | J13: =I16 -> 28707.65 | K13: =J16 -> 31019.232
B14: Additions During the Year | F14: =F8*F29 -> 22767.635 | G14: =G8*G29 -> 24594.512 | H14: =H8*H29 -> 26570.463 | I14: =I8*I29 -> 28707.65 | J14: =J8*J29 -> 31019.232 | K14: =K8*K29 -> 33519.44
B15: Cap WIP Transferred to Fixed Assets | F15: =-F13 -> -47183.61 | G15: =-G13 -> -22767.635 | H15: =-H13 -> -24594.512 | I15: =-I13 -> -26570.463 | J15: =-J13 -> -28707.65 | K15: =-K13 -> -31019.232
B16: Closing Cap WIP | C16: 13366.35 | D16: 6528.42 | E16: 47183.61 | F16: =SUM(F13:F15) -> 22767.635 | G16: =SUM(G13:G15) -> 24594.512 | H16: =SUM(H13:H15) -> 26570.463 | I16: =SUM(I13:I15) -> 28707.65 | J16: =SUM(J13:J15) -> 31019.232 | K16: =SUM(K13:K15) -> 33519.44
B19: Openning Gross PP&E | F19: 226007.44 | G19: =F21 -> 273191.05 | H19: =G21 -> 295958.69 | I19: =H21 -> 320553.2 | J19: =I21 -> 347123.66 | K19: =J21 -> 375831.31
B20: CapEx | C20: 15844.36 | D20: 30394.55 | E20: 15659.32 | F20: =ABS(F15) -> 47183.61 | G20: =ABS(G15) -> 22767.635 | H20: =ABS(H15) -> 24594.512 | I20: =ABS(I15) -> 26570.463 | J20: =ABS(J15) -> 28707.65 | K20: =ABS(K15) -> 31019.232
B21: Closing Gross PP&E | C21: 182751.51 | D21: 211986.7 | E21: 226007.44 | F21: =SUM(F19:F20) -> 273191.05 | G21: =SUM(G19:G20) -> 295958.69 | H21: =SUM(H19:H20) -> 320553.2 | I21: =SUM(I19:I20) -> 347123.66 | J21: =SUM(J19:J20) -> 375831.31 | K21: =SUM(K19:K20) -> 406850.54
B23: Accum Openning Dep | F23: =E25 -> 163099.9 | G23: =F25 -> 185563.83 | H23: =G25 -> 211175.57 | I23: =H25 -> 238918.6 | J23: =I25 -> 268964.06 | K23: =J25 -> 301497.04
B24: Dep of the Year | C24: 20312.12 | D24: 20840.08 | E24: 19767.99 | F24: =AVERAGE(E21:F21)*F30 -> 22463.932 | G24: =AVERAGE(F21:G21)*G30 -> 25611.738 | H24: =AVERAGE(G21:H21)*H30 -> 27743.035 | I24: =AVERAGE(H21:I21)*I30 -> 30045.459 | J24: =AVERAGE(I21:J21)*J30 -> 32532.974 | K24: =AVERAGE(J21:K21)*K30 -> 35220.683
B25: Accum Dep Closing | C25: 125095.15 | D25: 144851.11 | E25: 163099.9 | F25: =SUM(F23:F24) -> 185563.83 | G25: =SUM(G23:G24) -> 211175.57 | H25: =SUM(H23:H24) -> 238918.6 | I25: =SUM(I23:I24) -> 268964.06 | J25: =SUM(J23:J24) -> 301497.04 | K25: =SUM(K23:K24) -> 336717.72
B27: Net PP&E | F27: =F21-F25 -> 87627.218 | G27: =G21-G25 -> 84783.115 | H27: =H21-H25 -> 81634.593 | I27: =I21-I25 -> 78159.597 | J27: =J21-J25 -> 74334.274 | K27: =K21-K25 -> 70132.823
B29: CapEx as % of Revenue | C29: =C20/C8 -> 0.026272585 | D29: =D20/D8 -> 0.043527081 | E29: =E20/E8 -> 0.022631401 | F29: =AVERAGE($C29:$E29) -> 0.030810355 | G29: =AVERAGE($C29:$E29) -> 0.030810355 | H29: =AVERAGE($C29:$E29) -> 0.030810355 | I29: =AVERAGE($C29:$E29) -> 0.030810355 | J29: =AVERAGE($C29:$E29) -> 0.030810355 | K29: =AVERAGE($C29:$E29) -> 0.030810355
B30: Dep Rate | C30: =C24/AVERAGE(C21:C21) -> 0.11114611 | D30: =D24/AVERAGE(C21:D21) -> 0.10558937 | E30: =E24/AVERAGE(D21:E21) -> 0.090266002 | F30: =9% -> 0.09 | G30: =9% -> 0.09 | H30: =9% -> 0.09 | I30: =9% -> 0.09 | J30: =9% -> 0.09 | K30: =9% -> 0.09
B33: Intangible Schedule:
B35: Gross Openning Intangibles | F35: =E37 -> 13892.77 | G35: =F37 -> 14653.58 | H35: =G37 -> 15475.438 | I35: =H37 -> 16363.325 | J35: =I37 -> 16363.325 | K35: =J37 -> 16363.325
B36: Additions During the Year | C36: 1016.97 | D36: 696.95 | E36: 279.76 | F36: =F8*F45 -> 760.81024 | G36: =G8*G45 -> 821.85772 | H36: =H8*H45 -> 887.88667 | I36: 0 | J36: 0 | K36: 0
B37: Gross Closing Intangibles | C37: 13051.25 | D37: 13748.2 | E37: 13892.77 | F37: =SUM(F35:F36) -> 14653.58 | G37: =SUM(G35:G36) -> 15475.438 | H37: =SUM(H35:H36) -> 16363.325 | I37: =SUM(I35:I36) -> 16363.325 | J37: =SUM(J35:J36) -> 16363.325 | K37: =SUM(K35:K36) -> 16363.325
B39: Accum Openning Amount | F39: =E41 -> 11941.76 | G39: =F41 -> 13083.614 | H39: =G41 -> 14271.614 | I39: =H41 -> 15515.614 | J39: =I41 -> 15515.614 | K39: =J41 -> 15515.614
B40: Amor of the Year | C40: 1501.34 | D40: 1142.01 | E40: 1154.01 | F40: =AVERAGE(E37:F37)*F46 -> 1141.854 | G40: 1188 | H40: 1244 | I40: 0 | J40: 0 | K40: 0
B41: Accum Closing Amorti | C41: 9780.93 | D41: 10922.94 | E41: 11941.76 | F41: =SUM(F39:F40) -> 13083.614 | G41: =SUM(G39:G40) -> 14271.614 | H41: =SUM(H39:H40) -> 15515.614 | I41: =SUM(I39:I40) -> 15515.614 | J41: =SUM(J39:J40) -> 15515.614 | K41: =SUM(K39:K40) -> 15515.614
B43: Net Intangibles | C43: =C37-C41 -> 3270.32 | D43: =D37-D41 -> 2825.26 | E43: =E37-E41 -> 1951.01 | F43: =F37-F41 -> 1569.9662 | G43: =G37-G41 -> 1203.8239 | H43: =H37-H41 -> 847.71061 | I43: =I37-I41 -> 847.71061 | J43: =J37-J41 -> 847.71061 | K43: =K37-K41 -> 847.71061
B45: Additions as % of Revenue | C45: =C36/C8 -> 0.0016863054 | D45: =D36/D8 -> 0.00099808021 | E45: =E36/E8 -> 0.00040431901 | F45: =AVERAGE($C45:$E45) -> 0.0010295682 | G45: =AVERAGE($C45:$E45) -> 0.0010295682 | H45: =AVERAGE($C45:$E45) -> 0.0010295682 | I45: =AVERAGE($C45:$E45) -> 0.0010295682 | J45: =AVERAGE($C45:$E45) -> 0.0010295682 | K45: =J45 -> 0.0010295682
B46: Depriciation Rate | C46: =C40/AVERAGE(C37:C37) -> 0.11503419 | D46: =D40/AVERAGE(C37:D37) -> 0.085226376 | E46: =E40/AVERAGE(D37:E37) -> 0.083499964 | F46: 0.08 | G46: 0.08 | H46: 0.08 | I46: 0.08 | J46: 0.08 | K46: 0.08
B48: Right of use Assets
B50: Openning Gross Right of use | F50: =E52 -> 7031.93 | G50: =F52 -> 9124.1513 | H50: =G52 -> 11384.253 | I50: =H52 -> 13825.933 | J50: =I52 -> 16464.009 | K50: =J52 -> 19314.507
B51: CapEx | C51: 0.11 | D51: 5720.36 | E51: 208.81 | F51: =F61*F8 -> 2092.2213 | G51: =G61*G8 -> 2260.1013 | H51: =H61*H8 -> 2441.6803 | I51: =I61*I8 -> 2638.0762 | J51: =J61*J8 -> 2850.498 | K51: =K61*K8 -> 3080.2533
B52: Closing Gross PP&E | C52: 1102.76 | D52: 6823.12 | E52: 7031.93 | F52: =SUM(F50:F51) -> 9124.1513 | G52: =SUM(G50:G51) -> 11384.253 | H52: =SUM(H50:H51) -> 13825.933 | I52: =SUM(I50:I51) -> 16464.009 | J52: =SUM(J50:J51) -> 19314.507 | K52: =SUM(K50:K51) -> 22394.76
B54: Accum Openning Dep | F54: =E56 -> 839.43 | G54: =F56 -> 1202.9418 | H54: =G56 -> 1664.3809 | I54: =H56 -> 2231.6101 | J54: =I56 -> 2913.1338 | K54: =J56 -> 3718.1504
B55: Dep of the Year | C55: 85.2 | D55: 114.59 | E55: 199.73 | F55: =AVERAGE(E52:F52)*F63 -> 363.51183 | G55: =AVERAGE(F52:G52)*G63 -> 461.43909 | H55: =AVERAGE(G52:H52)*H63 -> 567.22917 | I55: =AVERAGE(H52:I52)*I63 -> 681.52369 | J55: =AVERAGE(I52:J52)*J63 -> 805.01661 | K55: =AVERAGE(J52:K52)*K63 -> 938.45852
B56: AccumDep Closing | C56: 525.11 | D56: 639.7 | E56: 839.43 | F56: =SUM(F54:F55) -> 1202.9418 | G56: =SUM(G54:G55) -> 1664.3809 | H56: =SUM(H54:H55) -> 2231.6101 | I56: =SUM(I54:I55) -> 2913.1338 | J56: =SUM(J54:J55) -> 3718.1504 | K56: =SUM(K54:K55) -> 4656.6089
B58: Net PP&E | C58: =C52-C56 -> 577.65 | D58: =D52-D56 -> 6183.42 | E58: =E52-E56 -> 6192.5 | F58: =F52-F56 -> 7921.2095 | G58: =G52-G56 -> 9719.8717 | H58: =H52-H56 -> 11594.323 | I58: =I52-I56 -> 13550.875 | J58: =J52-J56 -> 15596.357 | K58: =K52-K56 -> 17738.151
B61: CapEx as a % of Revenue | C61: =C51/C8 -> 1.823983e-07 | D61: =D51/D8 -> 0.0081919479 | E61: =E51/E8 -> 0.00030177957 | F61: =AVERAGE(C61:E61) -> 0.0028313033 | G61: =F61 -> 0.0028313033 | H61: =G61 -> 0.0028313033 | I61: =H61 -> 0.0028313033 | J61: =I61 -> 0.0028313033 | K61: =J61 -> 0.0028313033
B63: Dep Rate | C63: =C55/AVERAGE(C52:C52) -> 0.077260691 | D63: =D55/AVERAGE(C52:D52) -> 0.028915401 | E63: =E55/AVERAGE(D52:E52) -> 0.028831365 | F63: 0.045 | G63: 0.045 | H63: 0.045 | I63: 0.045 | J63: 0.045 | K63: 0.045
B66: Dep and Amor | F66: =SUM(F55,F40,F24) -> 23969.298 | G66: =SUM(G55,G40,G24) -> 27261.177 | H66: =SUM(H55,H40,H24) -> 29554.264 | I66: =SUM(I55,I40,I24) -> 30726.982 | J66: =SUM(J55,J40,J24) -> 33337.99 | K66: =SUM(K55,K40,K24) -> 36159.142
B68: WC Schedule
B70: Inventories | C70: =BS!C23 -> 34224.09 | D70: =BS!D23 -> 33156.29 | E70: =BS!E23 -> 34043.57 | F70: =F74*Expense!F11 -> 37021.343 | G70: =G74*Expense!G11 -> 39991.939 | H70: =H74*Expense!H11 -> 43204.935 | I70: =I74*Expense!I11 -> 46680.112 | J70: =J74*Expense!J11 -> 50438.863 | K70: =K74*Expense!K11 -> 54504.328
...

Sheet Debt
B6: Particulars ( in millions) | C6: 2023 | D6: =C6+1 -> 2024 | E6: =D6+1 -> 2025 | F6: =E6+1 -> 2026 | G6: =F6+1 -> 2027 | H6: =G6+1 -> 2028 | I6: =H6+1 -> 2029 | J6: =I6+1 -> 2030 | K6: =J6+1 -> 2031
B8: Free Cash Before Debt | F8: =CFS!F19+CFS!F25+(SUM(CFS!F27:F30)) -> 40535.666 | G8: =CFS!G19+CFS!G25+(SUM(CFS!G27:G30)) -> 43398.094 | H8: =CFS!H19+CFS!H25+(SUM(CFS!H27:H30)) -> 46694.907 | I8: =CFS!I19+CFS!I25+(SUM(CFS!I27:I30)) -> 50467.492 | J8: =CFS!J19+CFS!J25+(SUM(CFS!J27:J30)) -> 54237.227 | K8: =CFS!K19+CFS!K25+(SUM(CFS!K27:K30)) -> 58313.162
B9: Add: Openning Cash Balance | F9: =BS!E26 -> 48457.17 | G9: =BS!F26 -> 86434.466 | H9: =BS!G26 -> 124472.68 | I9: =BS!H26 -> 171167.59 | J9: =BS!I26 -> 221635.08 | K9: =BS!J26 -> 275872.3
B10: Less: Minimum cash Balance | C10: 0.02 | F10: =$C$10*'Revised IS'!F8 -> 14779.21 | G10: =$C$10*'Revised IS'!G8 -> 15965.095 | H10: =$C$10*'Revised IS'!H8 -> 17247.748 | I10: =$C$10*'Revised IS'!I8 -> 18635.066 | J10: =$C$10*'Revised IS'!J8 -> 20135.589 | K10: =$C$10*'Revised IS'!K8 -> 21758.554
B11: Free Cash For Debt | F11: =SUM(F8:F9)-F10 -> 74213.626 | G11: =SUM(G8:G9)-G10 -> 113867.46 | H11: =SUM(H8:H9)-H10 -> 153919.84 | I11: =SUM(I8:I9)-I10 -> 203000.01 | J11: =SUM(J8:J9)-J10 -> 255736.72 | K11: =SUM(K8:K9)-K10 -> 312426.91
B13: ST Debt | C13: =BS!C55 -> 4520.34 | D13: =BS!D55 -> 1451.18 | E13: =BS!E55 -> 2558.37 | F13: =E20 -> 5359.88
B16: Debt Paid | F16: =-E13 -> -2558.37 | G16: =-F13 -> -5359.88
B17: Borrowings
B20: LT Debt | C20: =BS!C46 -> 7065.66 | D20: =BS!D46 -> 6227.97 | E20: =BS!E46 -> 5359.88 | F20: =BS!F46 -> 0
B22: Total Debt: | C22: =C20+C13 -> 11586 | D22: =D20+D13 -> 7679.15 | E22: =E20+E13 -> 7918.25 | F22: =F20+F13 -> 5359.88 | G22: =G20+G13 -> 0
E24: 625 | F24: =AVERAGE(E22:F22)*F25 -> 532.06504 | G24: =AVERAGE(F22:G22)*G25 -> 214.77458 | H24: =AVERAGE(G22:H22)*H25 -> 0
B25: Rate | E25: =$E$24/AVERAGE(D22:E22) -> 0.080141562 | F25: =E25 -> 0.080141562 | G25: =F25 -> 0.080141562 | H25: =G25 -> 0.080141562 | I25: =H25 -> 0.080141562 | J25: =I25 -> 0.080141562 | K25: =J25 -> 0.080141562

Sheet Dcf Model
B6: Particulars ( in millions) | C6: 2023 | D6: 2024 | E6: 2025 | F6: 2026 | G6: 2027 | H6: 2028 | I6: 2029 | J6: 2030 | K6: 2031
B8: EBIT | F8: ='Revised IS'!F18 -> 71854.242 | G8: ='Revised IS'!G18 -> 74255.615 | H8: ='Revised IS'!H18 -> 80118.499 | I8: ='Revised IS'!I18 -> 87767.279 | J8: ='Revised IS'!J18 -> 94697.603 | K8: ='Revised IS'!K18 -> 102196.36
B9: Tax Rate | F9: 0.26 | G9: 0.26 | H9: 0.26 | I9: 0.26 | J9: 0.26 | K9: 0.26
B10: NOPAT (EBIT *(1-Tax Rate) | F10: =F8*(1-F9) -> 53172.139 | G10: =G8*(1-G9) -> 54949.155 | H10: =H8*(1-H9) -> 59287.689 | I10: =I8*(1-I9) -> 64947.786 | J10: =J8*(1-J9) -> 70076.226 | K10: =K8*(1-K9) -> 75625.303
B11: NCC | F11: ='Revised IS'!F16 -> 23969.298 | G11: ='Revised IS'!G16 -> 27261.177 | H11: ='Revised IS'!H16 -> 29554.264 | I11: ='Revised IS'!I16 -> 30726.982 | J11: ='Revised IS'!J16 -> 33337.99 | K11: ='Revised IS'!K16 -> 36159.142
B12: Change in CA | F12: =SUM(CFS!F12:F14) -> -9176.9927 | G12: =SUM(CFS!G12:G14) -> -5385.0559 | H12: =SUM(CFS!H12:H14) -> -5824.4765 | I12: =SUM(CFS!I12:I14) -> -6299.7538 | J12: =SUM(CFS!J12:J14) -> -6813.8137 | K12: =SUM(CFS!K12:K14) -> -7369.8209
B13: Change in CL | F13: =SUM(CFS!F16:F17) -> 10062.126 | G13: =SUM(CFS!G16:G17) -> 6493.3651 | H13: =SUM(CFS!H16:H17) -> 7023.2237 | I13: =SUM(CFS!I16:I17) -> 7596.3188 | J13: =SUM(CFS!J16:J17) -> 8216.1784 | K13: =SUM(CFS!K16:K17) -> 8886.6185
B14: CapEx on PP&E | F14: =CFS!F21 -> -22767.635 | G14: =CFS!G21 -> -24594.512 | H14: =CFS!H21 -> -26570.463 | I14: =CFS!I21 -> -28707.65 | J14: =CFS!J21 -> -31019.232 | K14: =CFS!K21 -> -33519.44
B15: Additions to Intangibles | F15: =CFS!F22 -> -760.81024 | G15: =CFS!G22 -> -821.85772 | H15: =CFS!H22 -> -887.88667 | I15: =CFS!I22 -> 0 | J15: =CFS!J22 -> 0 | K15: =CFS!K22 -> 0
B16: Additions to Right to Use Asset | F16: =CFS!F23 -> -2092.2213 | G16: =CFS!G23 -> -2260.1013 | H16: =CFS!H23 -> -2441.6803 | I16: =CFS!I23 -> -2638.0762 | J16: =CFS!J23 -> -2850.498 | K16: =CFS!K23 -> -3080.2533
B18: FCFF | Unlevered FCF | F18: =SUM(F10:F16) -> 52405.903 | G18: =SUM(G10:G16) -> 55642.17 | H18: =SUM(H10:H16) -> 60140.671 | I18: =SUM(I10:I16) -> 65625.607 | J18: =SUM(J10:J16) -> 70946.851 | K18: =SUM(K10:K16) -> 76701.55
K19: =K18*(1+I31)/(C67-I31) -> 1118254.8
B21: Discount Period | F21: 0.5 | G21: =F21+1 -> 1.5 | H21: =G21+1 -> 2.5 | I21: =H21+1 -> 3.5 | J21: =I21+1 -> 4.5 | K21: =J21+1 -> 5.5
B23: PV of FCFF | F23: =F18/(1+$C$67)^F21 -> 49240.408 | G23: =G18/(1+$C$67)^G21 -> 46156.02 | H23: =H18/(1+$C$67)^H21 -> 44042.851 | I23: =I18/(1+$C$67)^I21 -> 42429.055 | J23: =J18/(1+$C$67)^J21 -> 40495.429 | K23: =K18/(1+$C$67)^K21 -> 38650.925
B24: PV of TV
B26: Sum of PV of Terminal Value | C26: =SUM(F23:K23) -> 261014.69 | F26: Terminal Value Calculations
B27: PV of Terminal Value | C27: =I45 -> 917110.44
F28: 1. Perpetual Method
B29: Implied Terminal Value | C29: =SUM(C26:C27) -> 1178125.1
B30: Less: Non Equity Claims | C30: =C62-BS!E26-BS!E27 -> -77289.4 | F30: Terminal FCF | I30: =K18 -> 76701.55
F31: Growth Rate | I31: 0.06
B32: Implied Equity Value | C32: =C29-C30 -> 1255414.5 | F32: Terminal Value | I32: =I30*(1+I31)/(C67-I31) -> 1118254.8
B33: Diluted Share Outstanding | C33: =C48 -> 812.5411
F34: PV of Terminal Value | I34: =I32/(1+C67)^6 -> 529465.83
B35: Implied Share Price | C35: =C32/C33 -> 1545.0474
F36: 2. Multiple Method
B37: WACC Analysis
F38: Terminal EBITDA | I38: =K8+CFS!K9 -> 138355.5
B39: Risk Free Rate | C39: 0.07 | F39: Assumed EBITDA Mutiple | I39: 14
B40: Beta | C40: 1.05 | I40: =I38*I39 -> 1936977
B41: Risk Premium | C41: 0.06 | F41: PV of Terminal Value | I41: =I40/(1+C67)^6 -> 917110.44
B43: Cost of Equity : Ke | C43: =C39+C40*C41 -> 0.133 | F43: Select Method | I43: 2
F45: PV of Terminal Value | H45: Debt | I45: =IF(I43=1,I34,I41) -> 917110.44
B46: Basic Shares Outstanding | C46: 812.5411 | E46: Options | J46: Dillusion | K46: In The Money
B47: Dilusions | C47: =SUM(G50,J50) -> 0 | E47: 40 | F47: 1500 | G47: 0 | H47: 4000 | I47: 800
B48: Dilluted Shares Outs | C48: =SUM(C46:C47) -> 812.5411 | E48: 50 | F48: 2000 | H48: 3000 | I48: 2500
B49: Market Price | C49: 1825 | E49: 30 | F49: 1200
B50: Market Cap | C50: =C49*C48 -> 1482887.5
E51: =E47*F47/C49 -> 32.876712
B52: Risk Free Rate | C52: =C39 -> 0.07 | E52: =40-E51 -> 7.1232877
...
