Workbook

Sheet IS
B7: Particulars ( Rupess Lakh) | C7: 2022 | D7: 2023 | E7: 2024 | F7: 2025 | G7: 2026 | H7: 2027 | I7: 2028 | J7: 2029 | K7: 2030 | L7: 2031
B9: Revenue from operations | C9: 883298 | D9: 1184099 | E9: 1418582 | F9: 1529130 | G9: ='Revenue Model'!G9 -> 1706432.8 | H9: ='Revenue Model'!H9 -> 1919858.7 | I9: ='Revenue Model'!I9 -> 2164414.9 | J9: ='Revenue Model'!J9 -> 2445527.9 | K9: ='Revenue Model'!K9 -> 2769722 | L9: ='Revenue Model'!L9 -> 3144863.5
B10: Other income | C10: 17447 | D10: 22647 | E10: 40935 | F10: 50222 | G10: ='Revised IS '!G21 -> 51486.518 | H10: ='Revised IS '!H21 -> 52782.874 | I10: ='Revised IS '!I21 -> 54111.871 | J10: ='Revised IS '!J21 -> 55474.331 | K10: ='Revised IS '!K21 -> 56871.095 | L10: ='Revised IS '!L21 -> 58303.027
B11: Total Income (I+II) | C11: =SUM(C9:C10) -> 900745 | D11: =SUM(D9:D10) -> 1206746 | E11: =SUM(E9:E10) -> 1459517 | F11: =SUM(F9:F10) -> 1579352 | G11: =SUM(G9:G10) -> 1757919.3 | H11: =SUM(H9:H10) -> 1972641.6 | I11: =SUM(I9:I10) -> 2218526.8 | J11: =SUM(J9:J10) -> 2501002.2 | ... L11: =SUM(L9:L10) -> 3203166.5
B12: Expenses
B13: Cost of materials consumed | C13: 397396 | D13: 733522 | E13: 789153 | F13: 873183 | G13: =Expense!G28 -> 938538.05 | H13: =Expense!H28 -> 1055922.3 | I13: =Expense!I28 -> 1190428.2 | J13: =Expense!J28 -> 1345040.3 | K13: =Expense!K28 -> 1523347.1 | L13: =Expense!L28 -> 1729674.9
B14: Purchases of stock-in-trade | C14: 263975 | D14: 127147 | E14: 212042 | F14: 214000 | G14: =Expense!G29 -> 266203.52 | H14: =Expense!H29 -> 299497.96 | I14: =Expense!I29 -> 337648.73 | J14: =Expense!J29 -> 381502.35 | K14: =Expense!K29 -> 432076.63 | L14: =Expense!L29 -> 490598.7
B15: Changes in inventories of FG , WIP & SIT | C15: -931 | D15: -5805 | E15: -3786 | F15: -12275 | G15: =Expense!G30 -> -6825.7313 | H15: =Expense!H30 -> -7679.4348 | I15: =Expense!I30 -> -8657.6597 | J15: =Expense!J30 -> -9782.1116 | K15: =Expense!K30 -> -11078.888 | L15: =Expense!L30 -> -12579.454
B16: Employee benefits expenses | C16: 40514 | D16: 53085 | E16: 63016 | F16: 70260 | G16: ='Revised IS '!G13 -> 77381.432 | H16: ='Revised IS '!H13 -> 87059.633 | I16: ='Revised IS '!I13 -> 98149.499 | J16: ='Revised IS '!J13 -> 110897.1 | K16: ='Revised IS '!K13 -> 125598.3 | L16: ='Revised IS '!L13 -> 142609.8
B17: Finance costs | C17: 1266 | D17: 2523 | E17: 1936 | F17: 1942 | G17: =0 -> 0 | H17: =0 -> 0 | I17: =0 -> 0 | J17: =0 -> 0 | K17: =0 -> 0 | L17: =0 -> 0
B18: Depreciation and amortisation expenses | C18: 27890 | D18: 48460 | E18: 52558 | F18: 56082 | G18: ='Revised IS '!G17 -> 66414.741 | H18: ='Revised IS '!H17 -> 73547.89 | I18: ='Revised IS '!I17 -> 81178.929 | J18: ='Revised IS '!J17 -> 89774.78 | K18: ='Revised IS '!K17 -> 99478.246 | L18: ='Revised IS '!L17 -> 110457.38
B19: Other expenses | C19: 126727 | D19: 146771 | E19: 175501 | F19: 186148 | G19: ='Revised IS '!G14 -> 204771.94 | H19: ='Revised IS '!H14 -> 230383.04 | I19: ='Revised IS '!I14 -> 259729.79 | J19: ='Revised IS '!J14 -> 293463.35 | K19: ='Revised IS '!K14 -> 332366.64 | L19: ='Revised IS '!L14 -> 377383.62
B20: Vehicles / dies for own use | C20: -1445 | D20: -1565 | E20: -2607 | F20: -3749 | G20: =Expense!G31 -> -3412.8656 | H20: =Expense!H31 -> -3839.7174 | I20: =Expense!I31 -> -4328.8298 | J20: =Expense!J31 -> -4891.0558 | K20: =Expense!K31 -> -5539.444 | L20: =Expense!L31 -> -6289.727
B21: Total expenses (IV) | C21: =SUM(C13:C20) -> 855392 | D21: =SUM(D13:D20) -> 1104138 | E21: =SUM(E13:E20) -> 1287813 | F21: =SUM(F13:F20) -> 1385591 | G21: =SUM(G13:G20) -> 1543071.1 | H21: =SUM(H13:H20) -> 1734891.7 | I21: =SUM(I13:I20) -> 1954148.7 | J21: =SUM(J13:J20) -> 2206004.7 | ... L21: =SUM(L13:L20) -> 2831855.2
B22: Share of profit of associates | C22: 1464 | D22: 1558 | E22: 2263 | F22: 2152 | G22: 2152 | H22: 2152 | I22: 2152 | J22: 2152 | K22: 2152 | L22: 2152
B23: Share of profit of joint ventures | C23: 155 | D23: 216 | E23: 278 | F23: 287 | G23: 287 | H23: 287 | I23: 287 | J23: 287 | K23: 287 | L23: 287
B24: Profit before tax (III - IV + V + VI) | C24: =C11-C21+C22+C23 -> 46972 | D24: =D11-D21+D22+D23 -> 104382 | E24: =E11-E21+E22+E23 -> 174245 | F24: =F11-F21+F22+F23 -> 196200 | G24: =G11-G21+G22+G23 -> 217287.25 | H24: =H11-H21+H22+H23 -> 240188.92 | I24: =I11-I21+I22+I23 -> 266817.13 | J24: =J11-J21+J22+J23 -> 297436.47 | ... L24: =L11-L21+L22+L23 -> 373750.28
B25: Tax expense | C25: 8177 | D25: 21745 | E25: 39363 | F25: 51198 | G25: ='Revised IS '!G26 -> 48208.238 | H25: ='Revised IS '!H26 -> 53289.295 | I25: ='Revised IS '!I26 -> 59197.139 | J25: ='Revised IS '!J26 -> 65990.471 | K25: ='Revised IS '!K26 -> 73832.71 | L25: ='Revised IS '!L26 -> 82921.765
B26: Profit for the year (VII - VIII) | C26: =C24-C25 -> 38795 | D26: =D24-D25 -> 82637 | E26: =E24-E25 -> 134882 | F26: =F24-F25 -> 145002 | G26: =G24-G25 -> 169079.01 | H26: =H24-H25 -> 186899.62 | I26: =I24-I25 -> 207619.99 | J26: =J24-J25 -> 231446 | ... L26: =L24-L25 -> 290828.52

Sheet Revenue Model
B7: Particulars ( Rupess Lakh) | C7: 2022 | D7: 2023 | E7: 2024 | F7: 2025 | G7: 2026 | H7: 2027 | I7: 2028 | J7: 2029 | K7: 2030 | L7: 2031
B9: Revenue From Operation | C9: =SUM(C11:C13) -> 883298 | D9: =SUM(D11:D13) -> 1175713 | E9: =SUM(E11:E13) -> 1418582 | F9: =SUM(F11:F13) -> 1529130 | G9: =SUM(G11:G13) -> 1706432.8 | H9: =SUM(H11:H13) -> 1919858.7 | I9: =SUM(I11:I13) -> 2164414.9 | J9: =SUM(J11:J13) -> 2445527.9 | ... L9: =SUM(L11:L13) -> 3144863.5
B10: Sale of Product
B11: Vehicles | C11: 737912 | D11: 983198 | E11: 1170455 | F11: 1257091 | G11: =G16+G17 -> 1411838.8 | H11: =H16+H17 -> 1588805.9 | I11: =I16+I17 -> 1791822 | J11: =J16+J17 -> 2025487.2 | K11: =K16+K17 -> 2295343.6 | L11: =L16+L17 -> 2608085.5
B12: Spare Parts | C12: 100086 | D12: 141915 | E12: 178762 | F12: 194008 | G12: =G11*G39 -> 207199.28 | H12: =H11*H39 -> 233170.7 | I12: =I11*I39 -> 262965.02 | J12: =J11*J39 -> 297257.37 | K12: =K11*K39 -> 336861.08 | L12: =L11*L39 -> 382758.6
B13: Other Operating Revenue | C13: 45300 | D13: 50600 | E13: 69365 | F13: 78031 | G13: =F13*(1+G40) -> 87394.72 | H13: =G13*(1+H40) -> 97882.086 | I13: =H13*(1+I40) -> 109627.94 | J13: =I13*(1+J40) -> 122783.29 | K13: =J13*(1+K40) -> 137517.28 | L13: =K13*(1+L40) -> 154019.36
B15: Vehicle Revenue
B16: Revenue in Domestic | C16: =C36*C11 -> 631476.76 | D16: =D36*D11 -> 853516.2 | E16: =E36*E11 -> 1015294.8 | F16: =F36*F11 -> 1069964.8 | G16: =(G20*G25)/1000 -> 1179208.3 | H16: =(H20*H25)/1000 -> 1299605.4 | I16: =(I20*I25)/1000 -> 1432295.1 | J16: =(J20*J25)/1000 -> 1578532.5 | K16: =(K20*K25)/1000 -> 1739700.6 | L16: =(L20*L25)/1000 -> 1917324.1
B17: Revenue in Export | C17: =C37*C11 -> 106435.24 | D17: =D37*D11 -> 129681.8 | E17: =E37*E11 -> 155160.22 | F17: =F37*F11 -> 187126.16 | G17: =(G21*G26)/1000 -> 232630.56 | H17: =(H21*H26)/1000 -> 289200.5 | I17: =(I21*I26)/1000 -> 359526.83 | J17: =(J21*J26)/1000 -> 446954.76 | K17: =(K21*K26)/1000 -> 555642.99 | L17: =(L21*L26)/1000 -> 690761.47
B19: Unit Sold
B20: Domestic | C20: 1414277 | D20: 1706831 | E20: 1852256 | F20: 1901681 | G20: =F20*(1+G29) -> 2034798.7 | H20: =G20*(1+H29) -> 2177234.6 | I20: =H20*(1+I29) -> 2329641 | J20: =I20*(1+J29) -> 2492715.9 | K20: =J20*(1+K29) -> 2667206 | L20: =K20*(1+L29) -> 2853910.4
B21: Export | C21: 238376 | D21: 259333 | E21: 283067 | F21: 332585 | G21: =F21*(1+G30) -> 401418.79 | H21: =G21*(1+H30) -> 484498.84 | I21: =H21*(1+I30) -> 584773.64 | J21: =I21*(1+J30) -> 705801.91 | K21: =J21*(1+K30) -> 851878.93 | L21: =K21*(1+L30) -> 1028188.9
B24: Average selling Price
B25: Domestic | C25: =(C16/C20*1000000)/1000 -> 446.50147 | D25: =(D16/D20*1000000)/1000 -> 500.059 | E25: =(E16/E20*1000000)/1000 -> 548.13956 | F25: =(F16/F20*1000000)/1000 -> 562.6416 | G25: =F25*(1+G33) -> 579.52085 | H25: =G25*(1+H33) -> 596.90647 | I25: =H25*(1+I33) -> 614.81367 | J25: =I25*(1+J33) -> 633.25808 | K25: =J25*(1+K33) -> 652.25582 | L25: =K25*(1+L33) -> 671.8235
B26: Export | C26: =(C17/C21*1000000)/1000 -> 446.50147 | D26: =(D17/D21*1000000)/1000 -> 500.059 | E26: =(E17/E21*1000000)/1000 -> 548.13956 | F26: =(F17/F21*1000000)/1000 -> 562.6416 | G26: =F26*(1+G34) -> 579.52085 | H26: =G26*(1+H34) -> 596.90647 | I26: =H26*(1+I34) -> 614.81367 | J26: =I26*(1+J34) -> 633.25808 | K26: =J26*(1+K34) -> 652.25582 | L26: =K26*(1+L34) -> 671.8235
B28: Growth in Vehicle Revenue
B29: Domestic | D29: =D16/C16-1 -> 0.35161933 | E29: =E16/D16-1 -> 0.18954366 | F29: =F16/E16-1 -> 0.053846492 | G29: 0.07 | H29: 0.07 | I29: 0.07 | J29: 0.07 | K29: 0.07 | L29: 0.07
B30: Export | D30: =D17/C17-1 -> 0.21841042 | E30: =E17/D17-1 -> 0.19646874 | F30: =F17/E17-1 -> 0.2060189 | G30: =AVERAGE($D30:$F30) -> 0.20696602 | H30: =AVERAGE($D30:$F30) -> 0.20696602 | I30: =AVERAGE($D30:$F30) -> 0.20696602 | J30: =AVERAGE($D30:$F30) -> 0.20696602 | K30: =AVERAGE($D30:$F30) -> 0.20696602 | L30: =AVERAGE($D30:$F30) -> 0.20696602
B32: Growth in Selling Price
B33: Domestic | D33: =D25/C25-1 -> 0.11994927 | E33: =E25/D25-1 -> 0.096149769 | F33: =F25/E25-1 -> 0.02645685 | G33: =3% -> 0.03 | H33: =3% -> 0.03 | I33: =3% -> 0.03 | J33: =3% -> 0.03 | K33: =3% -> 0.03 | L33: =3% -> 0.03
B34: Export | D34: =D26/C26-1 -> 0.11994927 | E34: =E26/D26-1 -> 0.096149769 | F34: =F26/E26-1 -> 0.02645685 | G34: 0.03 | H34: 0.03 | I34: 0.03 | J34: 0.03 | K34: 0.03 | L34: 0.03
B36: % of sales in Domestic | C36: =C20/SUM(C20,C21) -> 0.85576161 | D36: =D20/SUM(D20,D21) -> 0.86810205 | E36: =E20/SUM(E20,E21) -> 0.86743598 | F36: =F20/SUM(F20,F21) -> 0.85114351 | G36: =G20/SUM(G20,G21) -> 0.83522867 | H36: =H20/SUM(H20,H21) -> 0.8179762 | I36: =I20/SUM(I20,I21) -> 0.79935125 | J36: =J20/SUM(J20,J21) -> 0.77933469 | ... L36: =L20/SUM(L20,L21) -> 0.73514616
B37: % of sales in Export | C37: =C21/SUM(C20:C21) -> 0.14423839 | D37: =D21/SUM(D20:D21) -> 0.13189795 | E37: =E21/SUM(E20:E21) -> 0.13256402 | F37: =F21/SUM(F20:F21) -> 0.14885649 | G37: =G21/SUM(G20:G21) -> 0.16477133 | H37: =H21/SUM(H20:H21) -> 0.1820238 | I37: =I21/SUM(I20:I21) -> 0.20064875 | J37: =J21/SUM(J20:J21) -> 0.22066531 | ... L37: =L21/SUM(L20:L21) -> 0.26485384
B39: Spare Parts as % of Vehicles | C39: =C12/C11 -> 0.13563406 | D39: =D12/D11 -> 0.1443402 | E39: =E12/E11 -> 0.15272864 | F39: =F12/F11 -> 0.15433091 | G39: =AVERAGE($C39:$F39) -> 0.14675845 | H39: =AVERAGE($C39:$F39) -> 0.14675845 | I39: =AVERAGE($C39:$F39) -> 0.14675845 | J39: =AVERAGE($C39:$F39) -> 0.14675845 | K39: =AVERAGE($C39:$F39) -> 0.14675845 | L39: =AVERAGE($C39:$F39) -> 0.14675845
B40: Other Operating Revenue Growth rate | D40: =D13/C13-1 -> 0.11699779 | E40: =E13/D13-1 -> 0.3708498 | F40: =F13/E13-1 -> 0.12493332 | G40: 0.12 | H40: 0.12 | I40: 0.12 | J40: 0.12 | K40: 0.12 | L40: 0.12
G56: 1000

Sheet Revised IS 
B7: Particulars ( Rupess Lakh) | C7: 2022 | D7: 2023 | E7: 2024 | F7: 2025 | G7: 2026 | H7: 2027 | I7: 2028 | J7: 2029 | K7: 2030 | L7: 2031
B9: Revenue from Operation | C9: ='Revenue Model'!C9 -> 883298 | D9: ='Revenue Model'!D9 -> 1175713 | E9: ='Revenue Model'!E9 -> 1418582 | F9: ='Revenue Model'!F9 -> 1529130 | G9: ='Revenue Model'!G9 -> 1706432.8 | H9: ='Revenue Model'!H9 -> 1919858.7 | I9: ='Revenue Model'!I9 -> 2164414.9 | J9: ='Revenue Model'!J9 -> 2445527.9 | ... L9: ='Revenue Model'!L9 -> 3144863.5
B10: COGS | C10: =SUM(IS!C13,IS!C14,IS!C15,IS!C20) -> 658995 | D10: =SUM(IS!D13,IS!D14,IS!D15,IS!D20) -> 853299 | E10: =SUM(IS!E13,IS!E14,IS!E15,IS!E20) -> 994802 | F10: =SUM(IS!F13,IS!F14,IS!F15,IS!F20) -> 1071159 | G10: =Expense!G11 -> 1194503 | H10: =Expense!H11 -> 1343901.1 | I10: =Expense!I11 -> 1515090.4 | J10: =Expense!J11 -> 1711869.5 | K10: =Expense!K11 -> 1938805.4 | L10: =Expense!L11 -> 2201404.4
B12: Gross Profit | C12: =C9-C10 -> 224303 | D12: =D9-D10 -> 322414 | E12: =E9-E10 -> 423780 | F12: =F9-F10 -> 457971 | G12: =G9-G10 -> 511929.84 | H12: =H9-H10 -> 575957.61 | I12: =I9-I10 -> 649324.47 | J12: =J9-J10 -> 733658.37 | ... L12: =L9-L10 -> 943459.05
B13: Employee Benefit Expense | C13: =IS!C16 -> 40514 | D13: =IS!D16 -> 53085 | E13: =IS!E16 -> 63016 | F13: =IS!F16 -> 70260 | G13: =Expense!G12 -> 77381.432 | H13: =Expense!H12 -> 87059.633 | I13: =Expense!I12 -> 98149.499 | J13: =Expense!J12 -> 110897.1 | K13: =Expense!K12 -> 125598.3 | L13: =Expense!L12 -> 142609.8
B14: Other Expense | C14: =IS!C19 -> 126727 | D14: =IS!D19 -> 146771 | E14: =IS!E19 -> 175501 | F14: =IS!F19 -> 186148 | G14: =Expense!G13 -> 204771.94 | H14: =Expense!H13 -> 230383.04 | I14: =Expense!I13 -> 259729.79 | J14: =Expense!J13 -> 293463.35 | K14: =Expense!K13 -> 332366.64 | L14: =Expense!L13 -> 377383.62
B16: EBITDA | C16: =C12-C13-C14 -> 57062 | D16: =D12-D13-D14 -> 122558 | E16: =E12-E13-E14 -> 185263 | F16: =F12-F13-F14 -> 201563 | G16: =G12-G13-G14 -> 229776.47 | H16: =H12-H13-H14 -> 258514.93 | I16: =I12-I13-I14 -> 291445.19 | J16: =J12-J13-J14 -> 329297.92 | ... L16: =L12-L13-L14 -> 423465.63
B17: D&A | C17: =IS!C18 -> 27890 | D17: =IS!D18 -> 48460 | E17: =IS!E18 -> 52558 | F17: =IS!F18 -> 56082 | G17: ='BS Schedule '!G68 -> 66414.741 | H17: ='BS Schedule '!H68 -> 73547.89 | I17: ='BS Schedule '!I68 -> 81178.929 | J17: ='BS Schedule '!J68 -> 89774.78 | K17: ='BS Schedule '!K68 -> 99478.246 | L17: ='BS Schedule '!L68 -> 110457.38
B19: EBIT | C19: =C16-C17 -> 29172 | D19: =D16-D17 -> 74098 | E19: =E16-E17 -> 132705 | F19: =F16-F17 -> 145481 | G19: =G16-G17 -> 163361.73 | H19: =H16-H17 -> 184967.04 | I19: =I16-I17 -> 210266.26 | J19: =J16-J17 -> 239523.14 | ... L19: =L16-L17 -> 313008.25
B20: Finance Cost | C20: =IS!C17 -> 1266 | D20: =IS!D17 -> 2523 | E20: =IS!E17 -> 1936 | F20: =IS!F17 -> 1942 | G20: =IS!G17 -> 0 | H20: =IS!H17 -> 0 | I20: =IS!I17 -> 0 | J20: =IS!J17 -> 0 | ... L20: =IS!L17 -> 0
B21: Other Income | C21: =IS!C10 -> 17447 | D21: =IS!D10 -> 22647 | E21: =IS!E10 -> 40935 | F21: =IS!F10 -> 50222 | G21: =Expense!G24 -> 51486.518 | H21: =Expense!H24 -> 52782.874 | I21: =Expense!I24 -> 54111.871 | J21: =Expense!J24 -> 55474.331 | K21: =Expense!K24 -> 56871.095 | L21: =Expense!L24 -> 58303.027
B22: Share of profit of associates | C22: =IS!C22 -> 1464 | D22: =IS!D22 -> 1558 | E22: =IS!E22 -> 2263 | F22: =IS!F22 -> 2152 | G22: =F22 -> 2152 | H22: =G22 -> 2152 | I22: =H22 -> 2152 | J22: =I22 -> 2152 | K22: =J22 -> 2152 | L22: =K22 -> 2152
B23: Share of profit of joint ventures | C23: =IS!C23 -> 155 | D23: =IS!D23 -> 216 | E23: =IS!E23 -> 278 | F23: =IS!F23 -> 287 | G23: =F23 -> 287 | H23: =G23 -> 287 | I23: =H23 -> 287 | J23: =I23 -> 287 | K23: =J23 -> 287 | L23: =K23 -> 287
B25: Profit Before Tax | C25: =C19-C20+SUM(C21:C23) -> 46972 | D25: =D19-D20+SUM(D21:D23) -> 95996 | E25: =E19-E20+SUM(E21:E23) -> 174245 | F25: =F19-F20+SUM(F21:F23) -> 196200 | G25: =G19-G20+SUM(G21:G23) -> 217287.25 | H25: =H19-H20+SUM(H21:H23) -> 240188.92 | I25: =I19-I20+SUM(I21:I23) -> 266817.13 | J25: =J19-J20+SUM(J21:J23) -> 297436.47 | ... L25: =L19-L20+SUM(L21:L23) -> 373750.28
B26: Tax | C26: =IS!C25 -> 8177 | D26: =IS!D25 -> 21745 | E26: =IS!E25 -> 39363 | F26: =IS!F25 -> 51198 | G26: =G25*G39 -> 48208.238 | H26: =H25*H39 -> 53289.295 | I26: =I25*I39 -> 59197.139 | J26: =J25*J39 -> 65990.471 | K26: =K25*K39 -> 73832.71 | L26: =L25*L39 -> 82921.765
B28: Profit After Tax | C28: =C25-C26 -> 38795 | D28: =D25-D26 -> 74251 | E28: =E25-E26 -> 134882 | F28: =F25-F26 -> 145002 | G28: =G25-G26 -> 169079.01 | H28: =H25-H26 -> 186899.62 | I28: =I25-I26 -> 207619.99 | J28: =J25-J26 -> 231446 | ... L28: =L25-L26 -> 290828.52 | N28: =N25-N26 -> 0 | O28: =O25-O26 -> 0 | P28: =P25-P26 -> 0 | Q28: =Q25-Q26 -> 0 | R28: =R25-R26 -> 0 | S28: =S25-S26 -> 0 | T28: =T25-T26 -> 0 | U28: =U25-U26 -> 0 | ... XFD28: =XFD25-XFD26 -> 0
B29: Dividend | C29: =C33*C35 -> 18124.804 | D29: =D33*D35 -> 27187.205 | E29: =E33*E35 -> 39300.322 | F29: 42444 | G29: =G28*G37 -> 49032.914 | H29: =H28*H37 -> 54200.89 | I29: =I28*I37 -> 60209.797 | J29: =J28*J37 -> 67119.34 | K29: =K28*K37 -> 75095.732 | L29: =L28*L37 -> 84340.269
B31: Retained Earning | C31: =C28-C29 -> 20670.196 | D31: =D28-D29 -> 47063.795 | E31: =E28-E29 -> 95581.678 | F31: =F28-F29 -> 102558 | G31: =G28-G29 -> 120046.1 | H31: =H28-H29 -> 132698.73 | I31: =I28-I29 -> 147410.19 | J31: =J28-J29 -> 164326.66 | ... L31: =L28-L29 -> 206488.25
B33: Dividend Per Share | C33: 60 | D33: 90 | E33: 125 | F33: 135 | G33: =G29/G35 -> 155.95583 | H33: =H29/H35 -> 172.39328 | I33: =I29/I35 -> 191.50542 | J33: =J29/J35 -> 213.48216 | K33: =K29/K35 -> 238.85215 | L33: =L29/L35 -> 268.25566
B35: Shares | C35: =C42 -> 302.08006 | D35: =D42 -> 302.08006 | E35: =E42 -> 314.40257 | F35: =F42 -> 314.40257 | G35: =G42 -> 314.40257 | H35: =H42 -> 314.40257 | I35: =I42 -> 314.40257 | J35: =J42 -> 314.40257 | ... L35: =L42 -> 314.40257
B37: % co paying Dividend | C37: =C29/C28 -> 0.46719432 | D37: =D29/D28 -> 0.36615272 | E37: =E29/E28 -> 0.29136817 | F37: =F29/F28 -> 0.2927132 | G37: =29% -> 0.29 | H37: =29% -> 0.29 | I37: =29% -> 0.29 | J37: =29% -> 0.29 | K37: =29% -> 0.29 | L37: =29% -> 0.29
B39: Tax % | C39: =C26/C25 -> 0.17408243 | D39: =D26/D25 -> 0.22651985 | E39: =E26/E25 -> 0.22590605 | F39: =F26/F25 -> 0.26094801 | G39: =AVERAGE($C39:$F39) -> 0.22186409 | H39: =AVERAGE($C39:$F39) -> 0.22186409 | I39: =AVERAGE($C39:$F39) -> 0.22186409 | J39: =AVERAGE($C39:$F39) -> 0.22186409 | K39: =AVERAGE($C39:$F39) -> 0.22186409 | L39: =AVERAGE($C39:$F39) -> 0.22186409
C42: =302080060/1000000 -> 302.08006 | D42: =302080060/1000000 -> 302.08006 | E42: =314402574/1000000 -> 314.40257 | F42: =314402574/1000000 -> 314.40257 | G42: =314402574/1000000 -> 314.40257 | H42: =314402574/1000000 -> 314.40257 | I42: =314402574/1000000 -> 314.40257 | J42: =314402574/1000000 -> 314.40257 | K42: =314402574/1000000 -> 314.40257 | L42: =314402574/1000000 -> 314.40257
C43: =BS!C41/C42 -> 4.9986749 | D43: =BS!D41/D42 -> 4.9986749 | E43: =BS!E41/E42 -> 4.9999591 | F43: =BS!F41/F42 -> 4.9999591 | G43: =BS!G41/G42 -> 4.9999591 | H43: =BS!H41/H42 -> 4.9999591 | I43: =BS!I41/I42 -> 4.9999591 | J43: =BS!J41/J42 -> 4.9999591 | ... L43: =BS!L41/L42 -> 4.9999591

Sheet Expense
B7: Particulars ( Rupess Lakh) | C7: 2022 | D7: 2023 | E7: 2024 | F7: 2025 | G7: 2026 | H7: 2027 | I7: 2028 | J7: 2029 | K7: 2030 | L7: 2031
B9: Revenue | C9: ='Revenue Model'!C9 -> 883298 | D9: ='Revenue Model'!D9 -> 1175713 | E9: ='Revenue Model'!E9 -> 1418582 | F9: ='Revenue Model'!F9 -> 1529130 | G9: ='Revised IS '!G9 -> 1706432.8 | H9: ='Revised IS '!H9 -> 1919858.7 | I9: ='Revised IS '!I9 -> 2164414.9 | J9: ='Revised IS '!J9 -> 2445527.9 | K9: ='Revised IS '!K9 -> 2769722 | L9: ='Revised IS '!L9 -> 3144863.5
B11: Cogs | C11: ='Revised IS '!C10 -> 658995 | D11: ='Revised IS '!D10 -> 853299 | E11: ='Revised IS '!E10 -> 994802 | F11: ='Revised IS '!F10 -> 1071159 | G11: =G9*G17 -> 1194503 | H11: =H9*H17 -> 1343901.1 | I11: =I9*I17 -> 1515090.4 | J11: =J9*J17 -> 1711869.5 | K11: =K9*K17 -> 1938805.4 | L11: =L9*L17 -> 2201404.4
B12: Employeee benefit expense | C12: ='Revised IS '!C13 -> 40514 | D12: ='Revised IS '!D13 -> 53085 | E12: ='Revised IS '!E13 -> 63016 | F12: ='Revised IS '!F13 -> 70260 | G12: =G9*G18 -> 77381.432 | H12: =H9*H18 -> 87059.633 | I12: =I9*I18 -> 98149.499 | J12: =J9*J18 -> 110897.1 | K12: =K9*K18 -> 125598.3 | L12: =L9*L18 -> 142609.8
B13: Other Expense | C13: ='Revised IS '!C14 -> 126727 | D13: ='Revised IS '!D14 -> 146771 | E13: ='Revised IS '!E14 -> 175501 | F13: ='Revised IS '!F14 -> 186148 | G13: =G9*G19 -> 204771.94 | H13: =H9*H19 -> 230383.04 | I13: =I9*I19 -> 259729.79 | J13: =J9*J19 -> 293463.35 | K13: =K9*K19 -> 332366.64 | L13: =L9*L19 -> 377383.62
B14: ='Revised IS '!B17 -> D&A | C14: ='Revised IS '!C17 -> 27890 | D14: ='Revised IS '!D17 -> 48460 | E14: ='Revised IS '!E17 -> 52558 | F14: ='Revised IS '!F17 -> 56082 | G14: =G9*G26 -> 62505.704 | H14: =H9*H26 -> 70323.378 | I14: =I9*I26 -> 79281.339 | J14: =J9*J26 -> 89578.354 | K14: =K9*K26 -> 101453.41 | L14: =L9*L26 -> 115194.64
B15: Tax | C15: =IS!C25 -> 8177 | D15: =IS!D25 -> 21745 | E15: =IS!E25 -> 39363 | F15: =IS!F25 -> 51198
B17: Cogs as a % of revenue | C17: =C11/C9 -> 0.74606192 | D17: =D11/D9 -> 0.72577151 | E17: =E11/E9 -> 0.70126507 | F17: =F11/F9 -> 0.70050225 | G17: =70% -> 0.7 | H17: =70% -> 0.7 | I17: =70% -> 0.7 | J17: =70% -> 0.7 | K17: =70% -> 0.7 | L17: =70% -> 0.7
B18: Employee benefit expense as % of revenue | C18: =C12/C9 -> 0.04586674 | D18: =D12/D9 -> 0.045151325 | E18: =E12/E9 -> 0.044421824 | F18: =F12/F9 -> 0.045947696 | G18: =AVERAGE($C18:$F18) -> 0.045346896 | H18: =AVERAGE($C18:$F18) -> 0.045346896 | I18: =AVERAGE($C18:$F18) -> 0.045346896 | J18: =AVERAGE($C18:$F18) -> 0.045346896 | K18: =AVERAGE($C18:$F18) -> 0.045346896 | L18: =AVERAGE($C18:$F18) -> 0.045346896
B19: Other Expense as a % of revenue | C19: =C13/C9 -> 0.14347027 | D19: =D13/D9 -> 0.12483574 | E19: =E13/E9 -> 0.1237158 | F19: =F13/F9 -> 0.12173458 | G19: =12% -> 0.12 | H19: =12% -> 0.12 | I19: =12% -> 0.12 | J19: =12% -> 0.12 | K19: =12% -> 0.12 | L19: =12% -> 0.12
B21: Tax as % of Revenue | C21: =C15/IS!C24 -> 0.17408243 | D21: =D15/IS!D24 -> 0.20832136 | E21: =E15/IS!E24 -> 0.22590605 | F21: =F15/IS!F24 -> 0.26094801
B24: Other Income | C24: ='Revised IS '!C21 -> 17447 | D24: ='Revised IS '!D21 -> 22647 | E24: ='Revised IS '!E21 -> 40935 | F24: ='Revised IS '!F21 -> 50222 | G24: =F24*(1+G25) -> 51486.518 | H24: =G24*(1+H25) -> 52782.874 | I24: =H24*(1+I25) -> 54111.871 | J24: =I24*(1+J25) -> 55474.331 | K24: =J24*(1+K25) -> 56871.095 | L24: =K24*(1+L25) -> 58303.027
C25: =C24/C9 -> 0.019752111 | D25: =D24/D9 -> 0.019262354 | E25: =E24/E9 -> 0.02885628 | F25: =F24/F9 -> 0.032843512 | G25: =AVERAGE($C25:$F25) -> 0.025178564 | H25: =AVERAGE($C25:$F25) -> 0.025178564 | I25: =AVERAGE($C25:$F25) -> 0.025178564 | J25: =AVERAGE($C25:$F25) -> 0.025178564 | K25: =AVERAGE($C25:$F25) -> 0.025178564 | L25: =AVERAGE($C25:$F25) -> 0.025178564
C26: =C14/C9 -> 0.031574848 | D26: =D14/D9 -> 0.041217542 | E26: =E14/E9 -> 0.037049674 | F26: =F14/F9 -> 0.036675757 | G26: =AVERAGE($C26:$F26) -> 0.036629455 | H26: =AVERAGE($C26:$F26) -> 0.036629455 | I26: =AVERAGE($C26:$F26) -> 0.036629455 | J26: =AVERAGE($C26:$F26) -> 0.036629455 | K26: =AVERAGE($C26:$F26) -> 0.036629455 | L26: =AVERAGE($C26:$F26) -> 0.036629455
B28: Cost of materials consumed | C28: =IS!C13 -> 397396 | D28: =IS!D13 -> 733522 | E28: =IS!E13 -> 789153 | F28: =IS!F13 -> 873183 | G28: =G33*G9 -> 938538.05 | H28: =H33*H9 -> 1055922.3 | I28: =I33*I9 -> 1190428.2 | J28: =J33*J9 -> 1345040.3 | K28: =K33*K9 -> 1523347.1 | L28: =L33*L9 -> 1729674.9
B29: Purchases of stock-in-trade | C29: =IS!C14 -> 263975 | D29: =IS!D14 -> 127147 | E29: =IS!E14 -> 212042 | F29: =IS!F14 -> 214000 | G29: =G34*G9 -> 266203.52 | H29: =H34*H9 -> 299497.96 | I29: =I34*I9 -> 337648.73 | J29: =J34*J9 -> 381502.35 | K29: =K34*K9 -> 432076.63 | L29: =L34*L9 -> 490598.7
B30: Changes in inventories of FG , WIP & SIT | C30: =IS!C15 -> -931 | D30: =IS!D15 -> -5805 | E30: =IS!E15 -> -3786 | F30: =IS!F15 -> -12275 | G30: =G35*G9 -> -6825.7313 | H30: =H35*H9 -> -7679.4348 | I30: =I35*I9 -> -8657.6597 | J30: =J35*J9 -> -9782.1116 | K30: =K35*K9 -> -11078.888 | L30: =L35*L9 -> -12579.454
B31: Vehicles / dies for own use | C31: =IS!C20 -> -1445 | D31: =IS!D20 -> -1565 | E31: =IS!E20 -> -2607 | F31: =IS!F20 -> -3749 | G31: =G36*G9 -> -3412.8656 | H31: =H36*H9 -> -3839.7174 | I31: =I36*I9 -> -4328.8298 | J31: =J36*J9 -> -4891.0558 | K31: =K36*K9 -> -5539.444 | L31: =L36*L9 -> -6289.727
C33: =C28/C9 -> 0.44990026 | D33: =D28/D9 -> 0.62389546 | E33: =E28/E9 -> 0.55629706 | F33: =F28/F9 -> 0.57103255 | G33: =55% -> 0.55 | H33: =55% -> 0.55 | I33: =55% -> 0.55 | J33: =55% -> 0.55 | K33: =55% -> 0.55 | L33: =55% -> 0.55
C34: =C29/C9 -> 0.29885158 | D34: =D29/D9 -> 0.10814459 | E34: =E29/E9 -> 0.14947462 | F34: =F29/F9 -> 0.13994886 | G34: =15.6% -> 0.156 | H34: =15.6% -> 0.156 | I34: =15.6% -> 0.156 | J34: =15.6% -> 0.156 | K34: =15.6% -> 0.156 | L34: =15.6% -> 0.156
C35: =C30/C9 -> -0.0010540044 | D35: =D30/D9 -> -0.0049374295 | E35: =E30/E9 -> -0.0026688623 | F35: =F30/F9 -> -0.0080274404 | G35: =-0.4% -> -0.004 | H35: =-0.4% -> -0.004 | I35: =-0.4% -> -0.004 | J35: =-0.4% -> -0.004 | K35: =-0.4% -> -0.004 | L35: =-0.4% -> -0.004
C36: =C31/C9 -> -0.0016359145 | D36: =D31/D9 -> -0.0013311072 | E36: =E31/E9 -> -0.0018377507 | F36: =F31/F9 -> -0.0024517209 | G36: =-0.2% -> -0.002 | H36: =-0.2% -> -0.002 | I36: =-0.2% -> -0.002 | J36: =-0.2% -> -0.002 | K36: =-0.2% -> -0.002 | L36: =-0.2% -> -0.002

Sheet BS
B7: Particulars ( Rupess Lakh) | C7: 2022 | D7: 2023 | E7: 2024 | F7: 2025 | G7: 2026 | H7: 2027 | I7: 2028 | J7: 2029 | K7: 2030 | L7: 2031
B9: ASSETS
B10: Non-current assets
B11: Property, plant and equipment | C11: 128261 | D11: 166921 | E11: 267982 | F11: 318966 | G11: ='BS Schedule '!G28 -> 329907.14 | H11: ='BS Schedule '!H28 -> 334674.17 | I11: ='BS Schedule '!I28 -> 341732.29 | J11: ='BS Schedule '!J28 -> 351556.43 | K11: ='BS Schedule '!K28 -> 364728.44 | L11: ='BS Schedule '!L28 -> 381962.11
B12: Right-of-use assets | C12: 5712 | D12: 5904 | E12: 6129 | F12: 5960 | G12: 5960 | H12: 5960 | I12: 5960 | J12: 5960 | K12: 5960 | L12: 5960
B13: Capital work-in-progress | C13: 26462 | D13: 28152 | E13: 75043 | F13: 75272 | G13: ='BS Schedule '!G17 -> 75843.716 | H13: ='BS Schedule '!H17 -> 85329.594 | I13: ='BS Schedule '!I17 -> 96199.082 | J13: ='BS Schedule '!J17 -> 108693.36 | K13: ='BS Schedule '!K17 -> 123102.42 | L13: ='BS Schedule '!L17 -> 139775.87
B14: Intangible assets | C14: 3499 | D14: 5479 | E14: 4537 | F14: 4901 | G14: ='BS Schedule '!G63 -> 6654.2854 | H14: ='BS Schedule '!H63 -> 8500.1635 | I14: ='BS Schedule '!I63 -> 10459.718 | J14: ='BS Schedule '!J63 -> 12559.005 | K14: ='BS Schedule '!K63 -> 14830.245 | L14: ='BS Schedule '!L63 -> 17313.305
B15: Intangible assets under development | C15: 2903 | D15: 889 | E15: 2305 | F15: 4018 | G15: 4018 | H15: 4018 | I15: 4018 | J15: 4018 | K15: 4018 | L15: 4018
B16: Financial assets
B17: Investments | C17: 379346 | D17: 491843 | E17: 533838 | F17: 579278 | G17: 579278 | H17: 579278 | I17: 579278 | J17: 579278 | K17: 579278 | L17: 579278
B18: Loans | C18: 2 | D18: 2 | E18: 1 | F18: 1 | G18: 1 | H18: 1 | I18: 1 | J18: 1 | K18: 1 | L18: 1
B19: Other financial assets | C19: 375 | D19: 595 | E19: 2981 | F19: 3003 | G19: 3003 | H19: 3003 | I19: 3003 | J19: 3003 | K19: 3003 | L19: 3003
B20: Non-current tax assets (Net) | C20: 5446 | D20: 5749 | E20: 5838 | F20: 4969 | G20: 4969 | H20: 4969 | I20: 4969 | J20: 4969 | K20: 4969 | L20: 4969
B21: Deferred tax assets (Net) | C21: 1411 | D21: 2794 | E21: 467 | F21: 6 | G21: 6 | H21: 6 | I21: 6 | J21: 6 | K21: 6 | L21: 6
B22: Other non-current assets | C22: 25204 | D22: 21485 | E22: 28049 | F22: 28102 | G22: 28102 | H22: 28102 | I22: 28102 | J22: 28102 | K22: 28102 | L22: 28102
B23: Total non-current assets | C23: =SUM(C11:C22) -> 578621 | D23: =SUM(D11:D22) -> 729813 | E23: =SUM(E11:E22) -> 927170 | F23: =SUM(F11:F22) -> 1024476 | G23: =SUM(G11:G22) -> 1037742.1 | H23: =SUM(H11:H22) -> 1053840.9 | I23: =SUM(I11:I22) -> 1073728.1 | J23: =SUM(J11:J22) -> 1098145.8 | ... L23: =SUM(L11:L22) -> 1164388.3
B24: Current assets
B25: Inventories | C25: 35323 | D25: 42835 | E25: 53181 | F25: 69132 | G25: ='BS Schedule '!G73 -> 71670.178 | H25: ='BS Schedule '!H73 -> 80634.065 | I25: ='BS Schedule '!I73 -> 90905.426 | J25: ='BS Schedule '!J73 -> 102712.17 | K25: ='BS Schedule '!K73 -> 116328.32 | L25: ='BS Schedule '!L73 -> 132084.27
B26: Financial assets
B27: Investments | C27: 41001 | D27: 0 | E27: 39122 | F27: 83376 | G27: 83376 | H27: 83376 | I27: 83376 | J27: 83376 | K27: 83376 | L27: 83376
B28: Trade receivables | C28: 20345 | D28: 33014 | E28: 45968 | F28: 65397 | G28: ='BS Schedule '!G72 -> 68257.313 | H28: ='BS Schedule '!H72 -> 76794.348 | I28: ='BS Schedule '!I72 -> 86576.597 | J28: ='BS Schedule '!J72 -> 97821.116 | K28: ='BS Schedule '!K72 -> 110788.88 | L28: ='BS Schedule '!L72 -> 125794.54
B29: Cash and cash equivalents | C29: 351 | D29: 373 | E29: 26595 | F29: 1845 | G29: =CFS!G41 -> 113222 | H29: =CFS!H41 -> 239212.68 | I29: =CFS!I41 -> 377496.19 | J29: =CFS!J41 -> 529774.11 | K29: =CFS!K41 -> 698041.41 | L29: =CFS!L41 -> 884645.7
B30: Other bank balances | C30: 30071 | D30: 43 | E30: 1679 | F30: 3684 | G30: 3684 | H30: 3684 | I30: 3684 | J30: 3684 | K30: 3684 | L30: 3684
B31: Loans | C31: 305 | D31: 297 | E31: 327 | F31: 432 | G31: 432 | H31: 432 | I31: 432 | J31: 432 | K31: 432 | L31: 432
B32: Other financial assets | C32: 25930 | D32: 21934 | E32: 34186 | F32: 33489 | G32: 33489 | H32: 33489 | I32: 33489 | J32: 33489 | K32: 33489 | L32: 33489
B33: Other current assets | C33: 14608 | D33: 17660 | E33: 25077 | F33: 37684 | G33: 37684 | H33: 37684 | I33: 37684 | J33: 37684 | K33: 37684 | L33: 37684
B34: Assets classified as held for sale | E34: 203 | F34: 203 | G34: 203 | H34: 203 | I34: 203 | J34: 203 | K34: 203 | L34: 203
B35: Total current assets | C35: =SUM(C25:C34) -> 167934 | D35: =SUM(D25:D34) -> 116156 | E35: =SUM(E25:E34) -> 226338 | F35: =SUM(F25:F34) -> 295242 | G35: =SUM(G25:G34) -> 412017.49 | H35: =SUM(H25:H34) -> 555509.1 | I35: =SUM(I25:I34) -> 713846.21 | J35: =SUM(J25:J34) -> 889175.39 | ... L35: =SUM(L25:L34) -> 1301392.5
B37: Total assets | C37: =C35+C23 -> 746555 | D37: =D35+D23 -> 845969 | E37: =E35+E23 -> 1153508 | F37: =F35+F23 -> 1319718 | G37: =G35+G23 -> 1449759.6 | H37: =H35+H23 -> 1609350 | I37: =I35+I23 -> 1787574.3 | J37: =J35+J23 -> 1987321.2 | ... L37: =L35+L23 -> 2465780.8
B39: EQUITY AND LIABILITIES
B40: Equity
B41: Equity share capital | C41: 1510 | D41: 1510 | E41: 1572 | F41: 1572 | G41: 1572 | H41: 1572 | I41: 1572 | J41: 1572 | K41: 1572 | L41: 1572
B42: Other equity | C42: 551825 | D42: 616403 | E42: 854788 | F42: 960827 | G42: =F42+'Revised IS '!G31 -> 1080873.1 | H42: =G42+'Revised IS '!H31 -> 1213571.8 | I42: =H42+'Revised IS '!I31 -> 1360982 | J42: =I42+'Revised IS '!J31 -> 1525308.7 | K42: =J42+'Revised IS '!K31 -> 1709163.8 | L42: =K42+'Revised IS '!L31 -> 1915652
B43: Total equity | C43: =SUM(C41:C42) -> 553335 | D43: =SUM(D41:D42) -> 617913 | E43: =SUM(E41:E42) -> 856360 | F43: =SUM(F41:F42) -> 962399 | G43: =SUM(G41:G42) -> 1082445.1 | H43: =SUM(H41:H42) -> 1215143.8 | I43: =SUM(I41:I42) -> 1362554 | J43: =SUM(J41:J42) -> 1526880.7 | ... L43: =SUM(L41:L42) -> 1917224
B45: Liabilities
B46: Non-current liabilities
B47: Financial liabilities
B48: Lease liabilities | C48: 329 | D48: 249 | E48: 677 | F48: 586 | G48: 586 | H48: 586 | I48: 586 | J48: 586 | K48: 586 | L48: 586
B49: Other Financial Liabilities | E49: - | F49: 5 | G49: 5 | H49: 5 | I49: 5 | J49: 5 | K49: 5 | L49: 5
B50: Provisions | C50: 844 | D50: 884 | E50: 1448 | F50: 1260 | G50: 1260 | H50: 1260 | I50: 1260 | J50: 1260 | K50: 1260 | L50: 1260
...

Sheet BS Schedule 
B7: Particulars ( Rupess Lakh) | C7: 2022 | D7: 2023 | E7: 2024 | F7: 2025 | G7: 2026 | H7: 2027 | I7: 2028 | J7: 2029 | K7: 2030 | L7: 2031
B9: Revenue | C9: ='Revised IS '!C9 -> 883298 | D9: ='Revised IS '!D9 -> 1175713 | E9: ='Revised IS '!E9 -> 1418582 | F9: ='Revised IS '!F9 -> 1529130 | G9: ='Revised IS '!G9 -> 1706432.8 | H9: ='Revised IS '!H9 -> 1919858.7 | I9: ='Revised IS '!I9 -> 2164414.9 | J9: ='Revised IS '!J9 -> 2445527.9 | ... L9: ='Revised IS '!L9 -> 3144863.5
B10: Cogs | C10: =Expense!C11 -> 658995 | D10: =Expense!D11 -> 853299 | E10: =Expense!E11 -> 994802 | F10: =Expense!F11 -> 1071159 | G10: ='Revised IS '!G10 -> 1194503 | H10: ='Revised IS '!H10 -> 1343901.1 | I10: ='Revised IS '!I10 -> 1515090.4 | J10: ='Revised IS '!J10 -> 1711869.5 | K10: ='Revised IS '!K10 -> 1938805.4 | L10: ='Revised IS '!L10 -> 2201404.4
B12: Net PP&E
B14: Openning Gross Capital WIP | G14: =F17 -> 75272 | H14: =G17 -> 75843.716 | I14: =H17 -> 85329.594 | J14: =I17 -> 96199.082 | K14: =J17 -> 108693.36 | L14: =K17 -> 123102.42
B15: CapEx | G15: =G30*G9 -> 75843.716 | H15: =H30*H9 -> 85329.594 | I15: =I30*I9 -> 96199.082 | J15: =J30*J9 -> 108693.36 | K15: =K30*K9 -> 123102.42 | L15: =L30*L9 -> 139775.87
B16: Capital WIP Transferred to WIP | G16: =-F17 -> -75272 | H16: =-G17 -> -75843.716 | I16: =-H17 -> -85329.594 | J16: =-I17 -> -96199.082 | K16: =-J17 -> -108693.36 | L16: =-K17 -> -123102.42
B17: Closing Capital WIP | C17: =BS!C13 -> 26462 | D17: =BS!D13 -> 28152 | E17: =BS!E13 -> 75043 | F17: =BS!F13 -> 75272 | G17: =SUM(G14:G16) -> 75843.716 | H17: =SUM(H14:H16) -> 85329.594 | I17: =SUM(I14:I16) -> 96199.082 | J17: =SUM(J14:J16) -> 108693.36 | K17: =SUM(K14:K16) -> 123102.42 | L17: =SUM(L14:L16) -> 139775.87
B20: Openning Gross PPE | G20: =F22 -> 682914 | H20: =G22 -> 758186 | I20: =H22 -> 834029.72 | J20: =I22 -> 919359.31 | K20: =J22 -> 1015558.4 | L20: =K22 -> 1124251.8
B21: CapEX | C21: 14404 | D21: 65774 | E21: 51448 | F21: 105915 | G21: =ABS(G16) -> 75272 | H21: =ABS(H16) -> 75843.716 | I21: =ABS(I16) -> 85329.594 | J21: =ABS(J16) -> 96199.082 | K21: =ABS(K16) -> 108693.36 | L21: =ABS(L16) -> 123102.42
B22: Closing PPE | C22: 307047 | D22: 367541 | E22: 582638 | F22: 682914 | G22: =SUM(G20:G21) -> 758186 | H22: =SUM(H20:H21) -> 834029.72 | I22: =SUM(I20:I21) -> 919359.31 | J22: =SUM(J20:J21) -> 1015558.4 | K22: =SUM(K20:K21) -> 1124251.8 | L22: =SUM(L20:L21) -> 1247354.2
B24: Openning Amortization | G24: =F26 -> 363948 | H24: =G26 -> 428278.86 | I24: =H26 -> 499355.54 | J24: =I26 -> 577627.02 | K24: =J26 -> 664001.96 | L24: =K26 -> 759523.32
B25: Dep during Year | C25: 26110 | D25: 26003 | E25: 50166 | F25: 53884 | G25: =AVERAGE(F22:G22)*G32 -> 64330.861 | H25: =AVERAGE(G22:H22)*H32 -> 71076.683 | I25: =AVERAGE(H22:I22)*I32 -> 78271.477 | J25: =AVERAGE(I22:J22)*J32 -> 86374.937 | K25: =AVERAGE(J22:K22)*K32 -> 95521.358 | L25: =AVERAGE(K22:L22)*L32 -> 105868.75
B26: Closing Amortization | C26: 178786 | D26: 200620 | E26: 314656 | F26: 363948 | G26: =SUM(G24:G25) -> 428278.86 | H26: =SUM(H24:H25) -> 499355.54 | I26: =SUM(I24:I25) -> 577627.02 | J26: =SUM(J24:J25) -> 664001.96 | K26: =SUM(K24:K25) -> 759523.32 | L26: =SUM(L24:L25) -> 865392.06
B28: Net PP&E | C28: =C22-C26 -> 128261 | D28: =D22-D26 -> 166921 | E28: =E22-E26 -> 267982 | F28: =F22-F26 -> 318966 | G28: =G22-G26 -> 329907.14 | H28: =H22-H26 -> 334674.17 | I28: =I22-I26 -> 341732.29 | J28: =J22-J26 -> 351556.43 | ... L28: =L22-L26 -> 381962.11
B30: CapEX as % of Revenue | C30: =C21/C9 -> 0.016307067 | D30: =D21/D9 -> 0.055943925 | E30: =E21/E9 -> 0.036267202 | F30: =F21/F9 -> 0.069264876 | G30: =AVERAGE($C30:$F30) -> 0.044445768 | H30: =AVERAGE($C30:$F30) -> 0.044445768 | I30: =AVERAGE($C30:$F30) -> 0.044445768 | J30: =AVERAGE($C30:$F30) -> 0.044445768 | K30: =AVERAGE($C30:$F30) -> 0.044445768 | L30: =AVERAGE($C30:$F30) -> 0.044445768
B31: PPE | C31: =-CFS!C23/'Revised IS '!C$9 -> 0.036299188 | D31: =-CFS!D23/'Revised IS '!D$9 -> 0.052024601 | E31: =-CFS!E23/'Revised IS '!E$9 -> 0.062852905 | F31: =-CFS!F23/'Revised IS '!F$9 -> 0.067033542 | G31: =5% -> 0.05 | H31: =5% -> 0.05 | I31: =5% -> 0.05 | J31: =5% -> 0.05 | K31: =5% -> 0.05 | L31: =5% -> 0.05
B32: Depriciation Rate | D32: =D25/AVERAGE(C22:D22) -> 0.077092981 | E32: =E25/AVERAGE(D22:E22) -> 0.10559274 | F32: =F25/AVERAGE(E22:F22) -> 0.085154936 | G32: =AVERAGE($D32:$F32) -> 0.089280218 | H32: =AVERAGE($D32:$F32) -> 0.089280218 | I32: =AVERAGE($D32:$F32) -> 0.089280218 | J32: =AVERAGE($D32:$F32) -> 0.089280218 | K32: =AVERAGE($D32:$F32) -> 0.089280218 | L32: =AVERAGE($D32:$F32) -> 0.089280218
B35: Right of Use
B37: Openning Gross | D37: =D39-D38 -> 6346 | E37: =E39-E38 -> 6735 | F37: =E39 -> 7408 | G37: =F39 -> 7592 | H37: =G39 -> 8073.7909 | I37: =H39 -> 8615.8401 | J37: =I39 -> 9226.9368 | K37: =J39 -> 9917.4024 | L37: =K39 -> 10699.4
B38: CapEx during the Year | C38: 24 | D38: 389 | E38: 673 | F38: 454 | G38: =G47*G9 -> 481.79092 | H38: =H47*H9 -> 542.04917 | I38: =I47*I9 -> 611.0967 | J38: =J47*J9 -> 690.46559 | K38: =K47*K9 -> 781.99792 | L38: =L47*L9 -> 887.91464
B39: Closing Right of use Asset | C39: =D37 -> 6346 | D39: =E37 -> 6735 | E39: 7408 | F39: 7592 | G39: =SUM(G37:G38) -> 8073.7909 | H39: =SUM(H37:H38) -> 8615.8401 | I39: =SUM(I37:I38) -> 9226.9368 | J39: =SUM(J37:J38) -> 9917.4024 | K39: =SUM(K37:K38) -> 10699.4 | L39: =SUM(L37:L38) -> 11587.315
B41: Openning Amortization | G41: =F43 -> 1632 | H41: =G43 -> 1632 | I41: =H43 -> 1632 | J41: =I43 -> 1632 | K41: =J43 -> 1632 | L41: =K43 -> 1632
B42: Depriciation Rate | C42: 172 | D42: 174 | E42: 222 | F42: 372
B43: Closing Ammortization | E43: 1279 | F43: 1632 | G43: =SUM(G41:G42) -> 1632 | H43: =SUM(H41:H42) -> 1632 | I43: =SUM(I41:I42) -> 1632 | J43: =SUM(J41:J42) -> 1632 | K43: =SUM(K41:K42) -> 1632 | L43: =SUM(L41:L42) -> 1632
B45: Net Right of Use Asset | E45: =E39-E43 -> 6129 | F45: =F39-F43 -> 5960 | G45: =G39-G43 -> 6441.7909 | H45: =H39-H43 -> 6983.8401 | I45: =I39-I43 -> 7594.9368 | J45: =J39-J43 -> 8285.4024 | K45: =K39-K43 -> 9067.4003 | L45: =L39-L43 -> 9955.3149
B47: CapEx as % of Revenue | C47: =C38/C9 -> 2.7170898e-05 | D47: =D38/D9 -> 0.00033086306 | E47: =E38/E9 -> 0.00047441741 | F47: =F38/F9 -> 0.00029690085 | G47: =AVERAGE($C47:$F47) -> 0.00028233806 | H47: =AVERAGE($C47:$F47) -> 0.00028233806 | I47: =AVERAGE($C47:$F47) -> 0.00028233806 | J47: =AVERAGE($C47:$F47) -> 0.00028233806 | K47: =AVERAGE($C47:$F47) -> 0.00028233806 | L47: =AVERAGE($C47:$F47) -> 0.00028233806
B48: Depriciation Rate | D48: =D42/AVERAGE(C39:D39) -> 0.026603471 | E48: =E42/AVERAGE(D39:E39) -> 0.031393622 | F48: =F42/AVERAGE(E39:F39) -> 0.0496 | G48: =AVERAGE($D48:$F48) -> 0.035865698 | H48: =AVERAGE($D48:$F48) -> 0.035865698 | I48: =AVERAGE($D48:$F48) -> 0.035865698 | J48: =AVERAGE($D48:$F48) -> 0.035865698 | K48: =AVERAGE($D48:$F48) -> 0.035865698 | L48: =AVERAGE($D48:$F48) -> 0.035865698
B50: Intangibles Asset
B52: Openning Gross | G52: =F54 -> 20017 | H52: =G54 -> 23854.166 | I52: =H54 -> 28171.251 | J52: =I54 -> 33038.257 | K52: =J54 -> 38537.387 | L52: =K54 -> 44765.515
B53: CapEx during the Year | C53: 2865 | D53: 4060 | E53: 1228 | F53: 2190 | G53: =G60*G9 -> 3837.1658 | H53: =H60*H9 -> 4317.0854 | I53: =I60*I9 -> 4867.0061 | J53: =J60*J9 -> 5499.13 | K53: =K60*K9 -> 6228.1282 | L53: =L60*L9 -> 7071.6892
B54: Closing Right of use Asset | C54: 12539 | D54: 16599 | E54: 17827 | F54: 20017 | G54: =SUM(G52:G53) -> 23854.166 | H54: =SUM(H52:H53) -> 28171.251 | I54: =SUM(I52:I53) -> 33038.257 | J54: =SUM(J52:J53) -> 38537.387 | K54: =SUM(K52:K53) -> 44765.515 | L54: =SUM(L52:L53) -> 51837.205
B56: Openning Amortization | G56: =F58 -> 15116 | H56: =G58 -> 17199.88 | I56: =H58 -> 19671.088 | J56: =I58 -> 22578.539 | K56: =J58 -> 25978.382 | L56: =K58 -> 29935.27
B57: Depriciation Rate | C57: 1608 | D57: 2080 | E57: 2170 | F57: 1826 | G57: =AVERAGE(F54:G54)*G61 -> 2083.8804 | H57: =AVERAGE(G54:H54)*H61 -> 2471.2073 | I57: =AVERAGE(H54:I54)*I61 -> 2907.4516 | J57: =AVERAGE(I54:J54)*J61 -> 3399.8431 | K57: =AVERAGE(J54:K54)*K61 -> 3956.8879 | L57: =AVERAGE(K54:L54)*L61 -> 4588.6292
B58: Closing Ammortization | C58: 9040 | D58: 11120 | E58: 13290 | F58: 15116 | G58: =SUM(G56:G57) -> 17199.88 | H58: =SUM(H56:H57) -> 19671.088 | I58: =SUM(I56:I57) -> 22578.539 | J58: =SUM(J56:J57) -> 25978.382 | K58: =SUM(K56:K57) -> 29935.27 | L58: =SUM(L56:L57) -> 34523.9
B60: Additions as % of Revenue | C60: =C53/C9 -> 0.003243526 | D60: =D53/D9 -> 0.0034532237 | E60: =E53/E9 -> 0.00086565317 | F60: =F53/F9 -> 0.0014321869 | G60: =AVERAGE($C60:$F60) -> 0.0022486474 | H60: =AVERAGE($C60:$F60) -> 0.0022486474 | I60: =AVERAGE($C60:$F60) -> 0.0022486474 | J60: =AVERAGE($C60:$F60) -> 0.0022486474 | K60: =AVERAGE($C60:$F60) -> 0.0022486474 | L60: =AVERAGE($C60:$F60) -> 0.0022486474
B61: Depriciation Rate | D61: =D57/AVERAGE(C54:D54) -> 0.14276889 | E61: =E57/AVERAGE(D54:E54) -> 0.12606751 | F61: =F57/AVERAGE(E54:F54) -> 0.096501427 | G61: =9.5% -> 0.095 | H61: =9.5% -> 0.095 | I61: =9.5% -> 0.095 | J61: =9.5% -> 0.095 | K61: =9.5% -> 0.095 | L61: =9.5% -> 0.095
B63: Net Intangible | C63: =C54-C58 -> 3499 | D63: =D54-D58 -> 5479 | E63: =E54-E58 -> 4537 | F63: =F54-F58 -> 4901 | G63: =G54-G58 -> 6654.2854 | H63: =H54-H58 -> 8500.1635 | I63: =I54-I58 -> 10459.718 | J63: =J54-J58 -> 12559.005 | ... L63: =L54-L58 -> 17313.305
B65: CapEx as % of Revenuie | C65: =C53/C9 -> 0.003243526 | D65: =D53/D9 -> 0.0034532237 | E65: =E53/E9 -> 0.00086565317 | F65: =F53/F9 -> 0.0014321869
B66: Depriciation Rate | D66: =D57/AVERAGE(C54:D54) -> 0.14276889 | E66: =E57/AVERAGE(D54:E54) -> 0.12606751 | F66: =F57/AVERAGE(E54:F54) -> 0.096501427
...

Sheet CFS
B7: Particulars ( Rupess Lakh) | C7: 2022 | D7: 2023 | E7: 2024 | F7: 2025 | G7: 2026 | H7: 2027 | I7: 2028 | J7: 2029 | K7: 2030 | L7: 2031
B9: A. Cash flow from Operating Activities:
B11: Profit After Tax | G11: ='Revised IS '!G28 -> 169079.01 | H11: ='Revised IS '!H28 -> 186899.62 | I11: ='Revised IS '!I28 -> 207619.99 | J11: ='Revised IS '!J28 -> 231446 | K11: ='Revised IS '!K28 -> 258950.8 | L11: ='Revised IS '!L28 -> 290828.52
B12: Depreciation and amortisation expense | C12: 27890 | D12: 28257 | E12: 52558 | F12: 56082 | G12: ='Revised IS '!G17 -> 66414.741 | H12: ='Revised IS '!H17 -> 73547.89 | I12: ='Revised IS '!I17 -> 81178.929 | J12: ='Revised IS '!J17 -> 89774.78 | K12: ='Revised IS '!K17 -> 99478.246 | L12: ='Revised IS '!L17 -> 110457.38
B13: Operating Profit before Working Capital changes | C13: 58319 | D13: 111115 | E13: 186765 | F13: 203215 | G13: =SUM(G11:G12) -> 235493.75 | H13: =SUM(H11:H12) -> 260447.51 | I13: =SUM(I11:I12) -> 288798.92 | J13: =SUM(J11:J12) -> 321220.78 | K13: =SUM(K11:K12) -> 358429.05 | L13: =SUM(L11:L12) -> 401285.89
B14: Adjustments for changes in Working Capital : | F14: -
B15: (Increase)/decrease in inventories | C15: -4833 | D15: -7512 | E15: 1254 | F15: -15951 | G15: =-(BS!G25-BS!F25) -> -2538.1782 | H15: =-(BS!H25-BS!G25) -> -8963.8871 | I15: =-(BS!I25-BS!H25) -> -10271.361 | J15: =-(BS!J25-BS!I25) -> -11806.745 | K15: =-(BS!K25-BS!J25) -> -13616.152 | L15: =-(BS!L25-BS!K25) -> -15755.943
B16: (Increase)/decrease in trade receivables | C16: -7640 | D16: 12581 | E16: -13164 | F16: -19692 | G16: =-(BS!G28-BS!F28) -> -2860.3126 | H16: =-(BS!H28-BS!G28) -> -8537.0353 | I16: =-(BS!I28-BS!H28) -> -9782.2486 | J16: =-(BS!J28-BS!I28) -> -11244.519 | K16: =-(BS!K28-BS!J28) -> -12967.764 | L16: =-(BS!L28-BS!K28) -> -15005.66
B17: Increase/(decrease) in trade payables | C17: -3959 | D17: 20075 | E17: 33214 | F17: 35093 | G17: =BS!G58-BS!F58 -> 9995.5347 | H17: =BS!H58-BS!G58 -> 26891.661 | I17: =BS!I58-BS!H58 -> 30814.083 | J17: =BS!J58-BS!I58 -> 35420.235 | K17: =BS!K58-BS!J58 -> 40848.455 | L17: =BS!L58-BS!K58 -> 47267.83
B19: Net Cash from Operating Activities | C19: 18405 | D19: 92514 | E19: 168011 | F19: 161362 | G19: =SUM(G13:G17) -> 240090.8 | H19: =SUM(H13:H17) -> 269838.25 | I19: =SUM(I13:I17) -> 299559.39 | J19: =SUM(J13:J17) -> 333589.75 | K19: =SUM(K13:K17) -> 372693.59 | L19: =SUM(L13:L17) -> 417792.12
B21: B. Cash flow from Investing Activities:
B23: Payments for purchase of property, plant and equipment & capital WIP | C23: -32063 | D23: -61166 | E23: -89162 | F23: -102503 | G23: =-'BS Schedule '!G15 -> -75843.716 | H23: =-'BS Schedule '!H15 -> -85329.594 | I23: =-'BS Schedule '!I15 -> -96199.082 | J23: =-'BS Schedule '!J15 -> -108693.36 | K23: =-'BS Schedule '!K15 -> -123102.42 | L23: =-'BS Schedule '!L15 -> -139775.87
B24: purchase of intangible assets andintangibleassetunderDevelopment | C24: -2530 | D24: -2307 | E24: -2837 | F24: -3903 | G24: =-'BS Schedule '!G53 -> -3837.1658 | H24: =-'BS Schedule '!H53 -> -4317.0854 | I24: =-'BS Schedule '!I53 -> -4867.0061 | J24: =-'BS Schedule '!J53 -> -5499.13 | K24: =-'BS Schedule '!K53 -> -6228.1282 | L24: =-'BS Schedule '!L53 -> -7071.6892
B26: Net Cash (used in) Investing Activities | C26: -2392 | D26: -80361 | E26: -118648 | F26: -144561 | G26: =SUM(G23:G24) -> -79680.882 | H26: =SUM(H23:H24) -> -89646.679 | I26: =SUM(I23:I24) -> -101066.09 | J26: =SUM(J23:J24) -> -114192.49 | K26: =SUM(K23:K24) -> -129330.55 | L26: =SUM(L23:L24) -> -146847.56
B28: C. Cash flow from Financing Activities:
B30: Equity Issue | G30: 0 | H30: 0 | I30: 0 | J30: 0 | K30: 0 | L30: 0
B31: Equity Buyback | G31: 0 | H31: 0 | I31: 0 | J31: 0 | K31: 0 | L31: 0
B32: Options Conversions | G32: 0 | H32: 0 | I32: 0 | J32: 0 | K32: 0 | L32: 0
B33: Change in Debt | G33: 0 | H33: 0 | I33: 0 | J33: 0 | K33: 0 | L33: 0
B34: Payment of dividend on equity shares | C34: -13594 | D34: -18125 | E34: -27187 | F34: -39300 | G34: =-'Revised IS '!G29 -> -49032.914 | H34: =-'Revised IS '!H29 -> -54200.89 | I34: =-'Revised IS '!I29 -> -60209.797 | J34: =-'Revised IS '!J29 -> -67119.34 | K34: =-'Revised IS '!K29 -> -75095.732 | L34: =-'Revised IS '!L29 -> -84340.269
B36: Net Cash (used in) Financing Activities | C36: -16070 | D36: -12131 | E36: =SUM(E34:E34) -> -27187 | F36: =SUM(F34:F34) -> -39300 | G36: =SUM(G34:G34) -> -49032.914 | H36: =SUM(H34:H34) -> -54200.89 | I36: =SUM(I34:I34) -> -60209.797 | J36: =SUM(J34:J34) -> -67119.34 | K36: =SUM(K34:K34) -> -75095.732 | L36: =SUM(L34:L34) -> -84340.269
B38: Net Increase/(Decrease) in cash & cash equivalents | C38: =C36+C26+C19 -> -57 | D38: =D36+D26+D19 -> 22 | E38: =E36+E26+E19 -> 22176 | F38: =F36+F26+F19 -> -22499 | G38: =G36+G26+G19 -> 111377 | H38: =H36+H26+H19 -> 125990.68 | I38: =I36+I26+I19 -> 138283.51 | J38: =J36+J26+J19 -> 152277.92 | ... L38: =L36+L26+L19 -> 186604.29
B39: Cash and cash equivalents at the beg of the year | G39: =BS!F29 -> 1845 | H39: =G41 -> 113222 | I39: =H41 -> 239212.68 | J39: =I41 -> 377496.19 | K39: =J41 -> 529774.11 | L39: =K41 -> 698041.41
B41: Cash and cash equivalents at the end of the year | G41: =SUM(G38:G39) -> 113222 | H41: =SUM(H38:H39) -> 239212.68 | I41: =SUM(I38:I39) -> 377496.19 | J41: =SUM(J38:J39) -> 529774.11 | K41: =SUM(K38:K39) -> 698041.41 | L41: =SUM(L38:L39) -> 884645.7

Sheet DCF
B7: Particulars ( Rupess Lakh) | C7: 2022 | D7: 2023 | E7: 2024 | F7: 2025 | G7: 2026 | H7: 2027 | I7: 2028 | J7: 2029 | K7: 2030 | L7: 2031
B10: EBIT | G10: ='Revised IS '!G19 -> 163361.73 | H10: ='Revised IS '!H19 -> 184967.04 | I10: ='Revised IS '!I19 -> 210266.26 | J10: ='Revised IS '!J19 -> 239523.14 | K10: ='Revised IS '!K19 -> 273473.41 | L10: ='Revised IS '!L19 -> 313008.25
B11: Tax | G11: ='Revised IS '!H39 -> 0.22186409 | H11: ='Revised IS '!I39 -> 0.22186409 | I11: ='Revised IS '!J39 -> 0.22186409 | J11: ='Revised IS '!K39 -> 0.22186409 | K11: ='Revised IS '!L39 -> 0.22186409 | L11: ='Revised IS '!M39 -> 0
B12: NOPAT | G12: =G10*(1-G11) -> 127117.63 | H12: =H10*(1-H11) -> 143929.5 | I12: =I10*(1-I11) -> 163615.73 | J12: =J10*(1-J11) -> 186381.56 | K12: =K10*(1-K11) -> 212799.49 | L12: =L10*(1-L11) -> 313008.25
B13: NCC | G13: ='Revised IS '!G17 -> 66414.741 | H13: ='Revised IS '!H17 -> 73547.89 | I13: ='Revised IS '!I17 -> 81178.929 | J13: ='Revised IS '!J17 -> 89774.78 | K13: ='Revised IS '!K17 -> 99478.246 | L13: ='Revised IS '!L17 -> 110457.38
B14: Changes in Inventory | G14: =CFS!G15 -> -2538.1782 | H14: =CFS!H15 -> -8963.8871 | I14: =CFS!I15 -> -10271.361 | J14: =CFS!J15 -> -11806.745 | K14: =CFS!K15 -> -13616.152 | L14: =CFS!L15 -> -15755.943
B15: Changes in Recievable | G15: =CFS!G16 -> -2860.3126 | H15: =CFS!H16 -> -8537.0353 | I15: =CFS!I16 -> -9782.2486 | J15: =CFS!J16 -> -11244.519 | K15: =CFS!K16 -> -12967.764 | L15: =CFS!L16 -> -15005.66
B16: Changes in Payables | G16: =CFS!G17 -> 9995.5347 | H16: =CFS!H17 -> 26891.661 | I16: =CFS!I17 -> 30814.083 | J16: =CFS!J17 -> 35420.235 | K16: =CFS!K17 -> 40848.455 | L16: =CFS!L17 -> 47267.83
B17: Additions to PPE | G17: =CFS!G23 -> -75843.716 | H17: =CFS!H23 -> -85329.594 | I17: =CFS!I23 -> -96199.082 | J17: =CFS!J23 -> -108693.36 | K17: =CFS!K23 -> -123102.42 | L17: =CFS!L23 -> -139775.87
B18: Additions To Intangibles | G18: =CFS!G24 -> -3837.1658 | H18: =CFS!H24 -> -4317.0854 | I18: =CFS!I24 -> -4867.0061 | J18: =CFS!J24 -> -5499.13 | K18: =CFS!K24 -> -6228.1282 | L18: =CFS!L24 -> -7071.6892
B20: FCFF | Unlevered FCF | G20: =SUM(G12:G18) -> 118448.53 | H20: =SUM(H12:H18) -> 137221.45 | I20: =SUM(I12:I18) -> 154489.04 | J20: =SUM(J12:J18) -> 174332.81 | K20: =SUM(K12:K18) -> 197211.72 | L20: =SUM(L12:L18) -> 293124.29
B22: Discount Period | G22: 0.5 | H22: 1.5 | I22: 2.5 | J22: 3.5 | K22: 4.5 | L22: 5.5
B24: PV of FCFF | G24: =G20/(1+$C$52)^G22 -> 112272.03 | H24: =H20/(1+$C$52)^H22 -> 116855.09 | I24: =I20/(1+$C$52)^I22 -> 118197.17 | J24: =J20/(1+$C$52)^J22 -> 119831.86 | K24: =K20/(1+$C$52)^K22 -> 121789.45 | L24: =L20/(1+$C$52)^L22 -> 162634.44
B27: WACC Analysis | G27: Sum of PV of Terminal Value | J27: =SUM(G24:L24) -> 751580.05
G28: PV of Terminal Value | J28: =J44 -> 2194541.2
B29: Risk free Rate | C29: 0.07
B30: Beta | C30: 1.03 | G30: Implied Terminal Value | J30: =SUM(J27:J28) -> 2946121.3
B31: Risk Premium | C31: 0.0418 | G31: Less: Non Equity Claims | J31: =BS!G57+BS!H48-BS!H29-BS!H30 -> -242026.68
B33: Cost of Equity: Ke | C33: =C29+(C30*C31) -> 0.113054 | G33: Implied Equity Value | J33: =J30-J31 -> 3188148
G34: Diluted Share Outstanding | J34: =C37 -> 314.40257
B35: Basic Shares Outstanding | C35: ='Revised IS '!F35 -> 314.40257
B36: Dilusions | C36: 0 | G36: Implied Share Price | J36: =J33/J34 -> 10140.337
B37: Dilluted Shares Outs | C37: =SUM(C35:C36) -> 314.40257
B38: Market Price | C38: 13050 | G38: Terminal Value Calculation
B39: Market Cap | C39: =C38*C37 -> 4102953.6
G40: Terminal FCFF | J40: =L20 -> 293124.29
B41: Risk Free Rate | C41: 0.07 | G41: Growth Rate | J41: 0.04
B42: Creduit Spread | C42: 0.0115 | G42: Terminal Value | J42: =J40*(1+J41)/(C52-J41) -> 4172930.5
B44: Pre Tax Cost of Debt | C44: 0.0815 | G44: PV of Terminal Value | J44: =J42/(1+C52)^6 -> 2194541.2
B45: Post Tax Cost of Debt | C45: =C44*(1-G11) -> 0.063418077
B47: Total Debt | C47: 0
B49: Equity% | C49: =C39/(C39+C47) -> 1
B50: Debt% | C50: =1-C49 -> 0
B52: WACC | C52: =C49*C33 -> 0.113054
